Workbook

Sheet Сводка
A1: СВОДКА: ОБОРОТНЫЙ ФОНД ГАРАНТИЙНЫХ КОМПОНЕНТОВ ПО ПЛОЩАДКАМ (парк по SAP)
A3: Парк по SAP (машин)
A4: Площадка | B4: Модель | C4: Группа | D4: Всего машин | E4: в т.ч. план
A5: Красноярск | B5: NTE240 | C5: NTE | D5: =COUNTIFS('Парк (SAP)'!$B$11:$B$346,"Полюс Красноярск",'Парк (SAP)'!$C$11:$C$346,"NTE240") -> 122 | E5: 39
A6: Красноярск | B6: TR100 | C6: TR100 | D6: =COUNTIFS('Парк (SAP)'!$B$11:$B$346,"Полюс Красноярск",'Парк (SAP)'!$C$11:$C$346,"TR100") -> 22 | E6: 18
A7: Сухой Лог | B7: NTE240 | C7: NTE | D7: =COUNTIFS('Парк (SAP)'!$B$11:$B$346,"Полюс Сухой Лог",'Парк (SAP)'!$C$11:$C$346,"NTE240") -> 85 | E7: 85
A8: Сухой Лог | B8: TR100 | C8: TR100 | D8: =COUNTIFS('Парк (SAP)'!$B$11:$B$346,"Полюс Сухой Лог",'Парк (SAP)'!$C$11:$C$346,"TR100") -> 9 | E8: 0
A9: Магадан | B9: NTE200 | C9: NTE | D9: =COUNTIFS('Парк (SAP)'!$B$11:$B$346,"Полюс Магадан",'Парк (SAP)'!$C$11:$C$346,"NTE200") -> 55 | E9: 8
A10: Магадан | B10: TR100 | C10: TR100 | D10: =COUNTIFS('Парк (SAP)'!$B$11:$B$346,"Полюс Магадан",'Парк (SAP)'!$C$11:$C$346,"TR100") -> 7 | E10: 4
A11: Алдан | B11: TR100 | C11: TR100 | D11: =COUNTIFS('Парк (SAP)'!$B$11:$B$346,"Полюс Алдан",'Парк (SAP)'!$C$11:$C$346,"TR100") -> 36 | E11: 13
A12: ИТОГО | D12: ='Парк (SAP)'!F347 -> 336 | E12: =SUM(E5:E11) -> 167
A14: Расчётный месяц (1-е число) | C14: =DATE(YEAR(TODAY()),MONTH(TODAY()),1) -> 46204
A16: Потребность в компонентах по площадкам
A17: Площадка | B17: Модель | C17: Компонент | D17: Норма/10 | E17: Тек. месяц, шт | F17: Пик, шт
A18: Красноярск | B18: NTE240 | C18: ДВС | D18: =$D$5 -> 1 | E18: =INDEX('Потребность (компоненты)'!$C$14:$C$102,MATCH($C$14,'Потребность (компоненты)'!$A$14:$A$102,0)) -> 6 | F18: ='Потребность (компоненты)'!C104 -> 6
A19: Красноярск | B19: NTE240 | C19: Мотор-колесо | D19: =$D$6 -> 2 | E19: =INDEX('Потребность (компоненты)'!$D$14:$D$102,MATCH($C$14,'Потребность (компоненты)'!$A$14:$A$102,0)) -> 12 | F19: ='Потребность (компоненты)'!D104 -> 12
A20: Красноярск | B20: NTE240 | C20: Силовой генератор | D20: =$D$7 -> 1 | E20: =INDEX('Потребность (компоненты)'!$E$14:$E$102,MATCH($C$14,'Потребность (компоненты)'!$A$14:$A$102,0)) -> 6 | F20: ='Потребность (компоненты)'!E104 -> 6
A21: Красноярск | B21: TR100 | C21: ДВС | D21: =$D$8 -> 1 | E21: =INDEX('Потребность (компоненты)'!$F$14:$F$102,MATCH($C$14,'Потребность (компоненты)'!$A$14:$A$102,0)) -> 2 | F21: ='Потребность (компоненты)'!F104 -> 3
A22: Красноярск | B22: TR100 | C22: КПП | D22: =$D$9 -> 1 | E22: =INDEX('Потребность (компоненты)'!$G$14:$G$102,MATCH($C$14,'Потребность (компоненты)'!$A$14:$A$102,0)) -> 2 | F22: ='Потребность (компоненты)'!G104 -> 3
A23: Красноярск | B23: TR100 | C23: Бортовой редуктор | D23: =$D$10 -> 2 | E23: =INDEX('Потребность (компоненты)'!$H$14:$H$102,MATCH($C$14,'Потребность (компоненты)'!$A$14:$A$102,0)) -> 4 | F23: ='Потребность (компоненты)'!H104 -> 6
A24: Сухой Лог | B24: NTE240 | C24: ДВС | D24: =$D$5 -> 1 | E24: =INDEX('Потребность (компоненты)'!$I$14:$I$102,MATCH($C$14,'Потребность (компоненты)'!$A$14:$A$102,0)) -> 0 | F24: ='Потребность (компоненты)'!I104 -> 8
A25: Сухой Лог | B25: NTE240 | C25: Мотор-колесо | D25: =$D$6 -> 2 | E25: =INDEX('Потребность (компоненты)'!$J$14:$J$102,MATCH($C$14,'Потребность (компоненты)'!$A$14:$A$102,0)) -> 0 | F25: ='Потребность (компоненты)'!J104 -> 16
A26: Сухой Лог | B26: NTE240 | C26: Силовой генератор | D26: =$D$7 -> 1 | E26: =INDEX('Потребность (компоненты)'!$K$14:$K$102,MATCH($C$14,'Потребность (компоненты)'!$A$14:$A$102,0)) -> 0 | F26: ='Потребность (компоненты)'!K104 -> 8
A27: Сухой Лог | B27: TR100 | C27: ДВС | D27: =$D$8 -> 1 | E27: =INDEX('Потребность (компоненты)'!$L$14:$L$102,MATCH($C$14,'Потребность (компоненты)'!$A$14:$A$102,0)) -> 1 | F27: ='Потребность (компоненты)'!L104 -> 1
A28: Сухой Лог | B28: TR100 | C28: КПП | D28: =$D$9 -> 1 | E28: =INDEX('Потребность (компоненты)'!$M$14:$M$102,MATCH($C$14,'Потребность (компоненты)'!$A$14:$A$102,0)) -> 1 | F28: ='Потребность (компоненты)'!M104 -> 1
A29: Сухой Лог | B29: TR100 | C29: Бортовой редуктор | D29: =$D$10 -> 2 | E29: =INDEX('Потребность (компоненты)'!$N$14:$N$102,MATCH($C$14,'Потребность (компоненты)'!$A$14:$A$102,0)) -> 2 | F29: ='Потребность (компоненты)'!N104 -> 2
A30: Магадан | B30: NTE200 | C30: ДВС | D30: =$D$5 -> 1 | E30: =INDEX('Потребность (компоненты)'!$O$14:$O$102,MATCH($C$14,'Потребность (компоненты)'!$A$14:$A$102,0)) -> 2 | F30: ='Потребность (компоненты)'!O104 -> 4
A31: Магадан | B31: NTE200 | C31: Мотор-колесо | D31: =$D$6 -> 2 | E31: =INDEX('Потребность (компоненты)'!$P$14:$P$102,MATCH($C$14,'Потребность (компоненты)'!$A$14:$A$102,0)) -> 4 | F31: ='Потребность (компоненты)'!P104 -> 8
A32: Магадан | B32: NTE200 | C32: Силовой генератор | D32: =$D$7 -> 1 | E32: =INDEX('Потребность (компоненты)'!$Q$14:$Q$102,MATCH($C$14,'Потребность (компоненты)'!$A$14:$A$102,0)) -> 2 | F32: ='Потребность (компоненты)'!Q104 -> 4
A33: Магадан | B33: TR100 | C33: ДВС | D33: =$D$8 -> 1 | E33: =INDEX('Потребность (компоненты)'!$R$14:$R$102,MATCH($C$14,'Потребность (компоненты)'!$A$14:$A$102,0)) -> 1 | F33: ='Потребность (компоненты)'!R104 -> 1
A34: Магадан | B34: TR100 | C34: КПП | D34: =$D$9 -> 1 | E34: =INDEX('Потребность (компоненты)'!$S$14:$S$102,MATCH($C$14,'Потребность (компоненты)'!$A$14:$A$102,0)) -> 1 | F34: ='Потребность (компоненты)'!S104 -> 1
A35: Магадан | B35: TR100 | C35: Бортовой редуктор | D35: =$D$10 -> 2 | E35: =INDEX('Потребность (компоненты)'!$T$14:$T$102,MATCH($C$14,'Потребность (компоненты)'!$A$14:$A$102,0)) -> 2 | F35: ='Потребность (компоненты)'!T104 -> 2
A36: Алдан | B36: TR100 | C36: ДВС | D36: =$D$8 -> 1 | E36: =INDEX('Потребность (компоненты)'!$U$14:$U$102,MATCH($C$14,'Потребность (компоненты)'!$A$14:$A$102,0)) -> 3 | F36: ='Потребность (компоненты)'!U104 -> 3
A37: Алдан | B37: TR100 | C37: КПП | D37: =$D$9 -> 1 | E37: =INDEX('Потребность (компоненты)'!$V$14:$V$102,MATCH($C$14,'Потребность (компоненты)'!$A$14:$A$102,0)) -> 3 | F37: ='Потребность (компоненты)'!V104 -> 3
A38: Алдан | B38: TR100 | C38: Бортовой редуктор | D38: =$D$10 -> 2 | E38: =INDEX('Потребность (компоненты)'!$W$14:$W$102,MATCH($C$14,'Потребность (компоненты)'!$A$14:$A$102,0)) -> 6 | F38: ='Потребность (компоненты)'!W104 -> 6

Sheet Графики
A1: ГРАФИКИ: МАШИНЫ НА ГАРАНТИИ И ПОТРЕБНОСТЬ В КОМПОНЕНТАХ ПО ПЛОЩАДКАМ И МОДЕЛЯМ
A2: Раздел 1. Самосвалы на гарантии — по каждой площадке (линии = модели)
A37: Раздел 2. Потребность в оборотных компонентах — по каждой площадке и модели

Sheet Парк (SAP)
A1: ПОЛНЫЙ ПАРК КАРЬЕРНЫХ САМОСВАЛОВ NHL ПО ДАННЫМ SAP (NTE + TR100)
A2: Источник состава и дат ввода — выгрузка SAP. NTE (NTE240 Красноярск/Сухой Лог, NTE200 Магадан) — электромеханический привод: ДВС, мотор-колёса, силовой генератор. TR100 (Красноярск, Сухой Лог, Магадан, Алдан) — механический привод: ДВС, КПП, бортовые редукторы. В SAP нет даты окончания гарантии — она рассчитывается из даты ввода по сроку гарантии (параметры ниже). Строки без серийного № — плановые вводы.
A4: ПАРАМЕТРЫ СРОКА ГАРАНТИИ (жёлтые ячейки — редактируемые)
A5: NTE: дата смены срока гарантии (с этой даты — увеличенный срок) | D5: 45934
A6: NTE: срок гарантии до даты смены, мес | D6: 12
A7: NTE: срок гарантии с даты смены, мес | D7: 24
A8: TR100: срок гарантии, мес | D8: 24
A10: № | B10: Площадка | C10: Модель | D10: Группа | E10: Серийный № | F10: Гараж. № | G10: Статус | H10: Дата ввода | I10: Срок гар., мес | J10: Дата оконч. гарантии
A11: 1 | B11: Полюс Красноярск | C11: NTE240 | D11: NTE | E11: NHLTBABAVPB200021 | F11: 201 | G11: факт | H11: 45341 | I11: =IF(D11="TR100",$D$8,IF(H11<$D$5,$D$6,$D$7)) -> 12 | J11: =EDATE(H11,I11) -> 45707
A12: 2 | B12: Полюс Красноярск | C12: NTE240 | D12: NTE | E12: NHLTBABACPB200026 | F12: 202 | G12: факт | H12: 45347 | I12: =IF(D12="TR100",$D$8,IF(H12<$D$5,$D$6,$D$7)) -> 12 | J12: =EDATE(H12,I12) -> 45713
A13: 3 | B13: Полюс Красноярск | C13: NTE240 | D13: NTE | E13: NHLTBABACPB200017 | F13: 203 | G13: факт | H13: 45355 | I13: =IF(D13="TR100",$D$8,IF(H13<$D$5,$D$6,$D$7)) -> 12 | J13: =EDATE(H13,I13) -> 45720
A14: 4 | B14: Полюс Красноярск | C14: NTE240 | D14: NTE | E14: NHLTBABAAPB200022 | F14: 204 | G14: факт | H14: 45362 | I14: =IF(D14="TR100",$D$8,IF(H14<$D$5,$D$6,$D$7)) -> 12 | J14: =EDATE(H14,I14) -> 45727
A15: 5 | B15: Полюс Красноярск | C15: NTE240 | D15: NTE | E15: NHLTBABAKPB200015 | F15: 205 | G15: факт | H15: 45369 | I15: =IF(D15="TR100",$D$8,IF(H15<$D$5,$D$6,$D$7)) -> 12 | J15: =EDATE(H15,I15) -> 45734
A16: 6 | B16: Полюс Красноярск | C16: NTE240 | D16: NTE | E16: NHLTBABACPB200020 | F16: 206 | G16: факт | H16: 45376 | I16: =IF(D16="TR100",$D$8,IF(H16<$D$5,$D$6,$D$7)) -> 12 | J16: =EDATE(H16,I16) -> 45741
A17: 7 | B17: Полюс Красноярск | C17: NTE240 | D17: NTE | E17: NHLTBABAEPB200025 | F17: 208 | G17: факт | H17: 45380 | I17: =IF(D17="TR100",$D$8,IF(H17<$D$5,$D$6,$D$7)) -> 12 | J17: =EDATE(H17,I17) -> 45745
A18: 8 | B18: Полюс Красноярск | C18: NTE240 | D18: NTE | E18: NHLTBABAHPB200024 | F18: 209 | G18: факт | H18: 45383 | I18: =IF(D18="TR100",$D$8,IF(H18<$D$5,$D$6,$D$7)) -> 12 | J18: =EDATE(H18,I18) -> 45748
A19: 9 | B19: Полюс Красноярск | C19: NTE240 | D19: NTE | E19: NHLTBABAKPB200032 | F19: 207 | G19: факт | H19: 45389 | I19: =IF(D19="TR100",$D$8,IF(H19<$D$5,$D$6,$D$7)) -> 12 | J19: =EDATE(H19,I19) -> 45754
A20: 10 | B20: Полюс Красноярск | C20: NTE240 | D20: NTE | E20: NHLTBABALPB200023 | F20: 210 | G20: факт | H20: 45393 | I20: =IF(D20="TR100",$D$8,IF(H20<$D$5,$D$6,$D$7)) -> 12 | J20: =EDATE(H20,I20) -> 45758
A21: 11 | B21: Полюс Красноярск | C21: NTE240 | D21: NTE | E21: NHLTBABAAPB200019 | F21: 211 | G21: факт | H21: 45398 | I21: =IF(D21="TR100",$D$8,IF(H21<$D$5,$D$6,$D$7)) -> 12 | J21: =EDATE(H21,I21) -> 45763
A22: 12 | B22: Полюс Красноярск | C22: NTE240 | D22: NTE | E22: NHLTBABATPB200027 | F22: 212 | G22: факт | H22: 45412 | I22: =IF(D22="TR100",$D$8,IF(H22<$D$5,$D$6,$D$7)) -> 12 | J22: =EDATE(H22,I22) -> 45777
... A85: 75 | B85: Полюс Красноярск | C85: NTE240 | D85: NTE | E85: NHLTBABAKSB200105 | F85: 275 | G85: факт | H85: 45958 | I85: =IF(D85="TR100",$D$8,IF(H85<$D$5,$D$6,$D$7)) -> 24 | J85: =EDATE(H85,I85) -> 46688
A86: 76 | B86: Полюс Красноярск | C86: NTE240 | D86: NTE | G86: план | H86: 46058 | I86: =IF(D86="TR100",$D$8,IF(H86<$D$5,$D$6,$D$7)) -> 24 | J86: =EDATE(H86,I86) -> 46788
A87: 77 | B87: Полюс Красноярск | C87: NTE240 | D87: NTE | G87: план | H87: 46063 | I87: =IF(D87="TR100",$D$8,IF(H87<$D$5,$D$6,$D$7)) -> 24 | J87: =EDATE(H87,I87) -> 46793
A88: 78 | B88: Полюс Красноярск | C88: NTE240 | D88: NTE | G88: план | H88: 46073 | I88: =IF(D88="TR100",$D$8,IF(H88<$D$5,$D$6,$D$7)) -> 24 | J88: =EDATE(H88,I88) -> 46803
A89: 79 | B89: Полюс Красноярск | C89: NTE240 | D89: NTE | E89: NHLTBABACSB2A0135 | F89: 276 | G89: факт | H89: 46076 | I89: =IF(D89="TR100",$D$8,IF(H89<$D$5,$D$6,$D$7)) -> 24 | J89: =EDATE(H89,I89) -> 46806
A90: 80 | B90: Полюс Красноярск | C90: NTE240 | D90: NTE | E90: NHLTBABAJSB2A0134 | F90: 277 | G90: факт | H90: 46078 | I90: =IF(D90="TR100",$D$8,IF(H90<$D$5,$D$6,$D$7)) -> 24 | J90: =EDATE(H90,I90) -> 46808
A91: 81 | B91: Полюс Красноярск | C91: NTE240 | D91: NTE | G91: план | H91: 46081 | I91: =IF(D91="TR100",$D$8,IF(H91<$D$5,$D$6,$D$7)) -> 24 | J91: =EDATE(H91,I91) -> 46811
A92: 82 | B92: Полюс Красноярск | C92: NTE240 | D92: NTE | G92: план | H92: 46086 | I92: =IF(D92="TR100",$D$8,IF(H92<$D$5,$D$6,$D$7)) -> 24 | J92: =EDATE(H92,I92) -> 46817
A93: 83 | B93: Полюс Красноярск | C93: NTE240 | D93: NTE | E93: NHLTBABAKSB2A0133 | F93: 278 | G93: факт | H93: 46088 | I93: =IF(D93="TR100",$D$8,IF(H93<$D$5,$D$6,$D$7)) -> 24 | J93: =EDATE(H93,I93) -> 46819
A94: 84 | B94: Полюс Красноярск | C94: NTE240 | D94: NTE | G94: план | H94: 46091 | I94: =IF(D94="TR100",$D$8,IF(H94<$D$5,$D$6,$D$7)) -> 24 | J94: =EDATE(H94,I94) -> 46822
A95: 85 | B95: Полюс Красноярск | C95: NTE240 | D95: NTE | G95: план | H95: 46101 | I95: =IF(D95="TR100",$D$8,IF(H95<$D$5,$D$6,$D$7)) -> 24 | J95: =EDATE(H95,I95) -> 46832
A96: 86 | B96: Полюс Красноярск | C96: NTE240 | D96: NTE | E96: NHLTBABAVSB2A0136 | F96: 279 | G96: факт | H96: 46102 | I96: =IF(D96="TR100",$D$8,IF(H96<$D$5,$D$6,$D$7)) -> 24 | J96: =EDATE(H96,I96) -> 46833
A97: 87 | B97: Полюс Красноярск | C97: NTE240 | D97: NTE | E97: NHLTBABAHSB2A0139 | F97: 280 | G97: факт | H97: 46106 | I97: =IF(D97="TR100",$D$8,IF(H97<$D$5,$D$6,$D$7)) -> 24 | J97: =EDATE(H97,I97) -> 46837
A98: 88 | B98: Полюс Красноярск | C98: NTE240 | D98: NTE | E98: NHLTBABAASB2A0137 | F98: 281 | G98: факт | H98: 46109 | I98: =IF(D98="TR100",$D$8,IF(H98<$D$5,$D$6,$D$7)) -> 24 | J98: =EDATE(H98,I98) -> 46840
A99: 89 | B99: Полюс Красноярск | C99: NTE240 | D99: NTE | G99: план | H99: 46109 | I99: =IF(D99="TR100",$D$8,IF(H99<$D$5,$D$6,$D$7)) -> 24 | J99: =EDATE(H99,I99) -> 46840
A100: 90 | B100: Полюс Красноярск | C100: NTE240 | D100: NTE | E100: NHLTBABALSB2A0141 | F100: 282 | G100: факт | H100: 46117 | I100: =IF(D100="TR100",$D$8,IF(H100<$D$5,$D$6,$D$7)) -> 24 | J100: =EDATE(H100,I100) -> 46848
A101: 91 | B101: Полюс Красноярск | C101: NTE240 | D101: NTE | E101: NHLTBABACSB2A0144 | F101: 283 | G101: факт | H101: 46120 | I101: =IF(D101="TR100",$D$8,IF(H101<$D$5,$D$6,$D$7)) -> 24 | J101: =EDATE(H101,I101) -> 46851
A102: 92 | B102: Полюс Красноярск | C102: NTE240 | D102: NTE | F102: 285 | G102: план | H102: 46124 | I102: =IF(D102="TR100",$D$8,IF(H102<$D$5,$D$6,$D$7)) -> 24 | J102: =EDATE(H102,I102) -> 46855
A103: 93 | B103: Полюс Красноярск | C103: NTE240 | D103: NTE | F103: 286 | G103: план | H103: 46129 | I103: =IF(D103="TR100",$D$8,IF(H103<$D$5,$D$6,$D$7)) -> 24 | J103: =EDATE(H103,I103) -> 46860
A104: 94 | B104: Полюс Красноярск | C104: NTE240 | D104: NTE | F104: 287 | G104: план | H104: 46130 | I104: =IF(D104="TR100",$D$8,IF(H104<$D$5,$D$6,$D$7)) -> 24 | J104: =EDATE(H104,I104) -> 46861
...

Sheet Гарантия (машины)
A1: САМОСВАЛЫ НА ГАРАНТИИ ПО МЕСЯЦАМ — ПО ПЛОЩАДКАМ И МОДЕЛЯМ
A2: Кол-во самосвалов, находящихся на гарантии в каждом месяце (введён ≤ конца месяца и гарантия не истекла до начала месяца), по каждой комбинации «площадка × модель».
A4: Месяц | B4: Год | C4: Красноярск NTE240 | D4: Красноярск TR100 | E4: Сухой Лог NTE240 | F4: Сухой Лог TR100 | G4: Магадан NTE200 | H4: Магадан TR100 | I4: Алдан TR100 | J4: ВСЕГО
A5: 45323 | B5: =YEAR(A5) -> 2024 | C5: =SUMPRODUCT(('Парк (SAP)'!$B$11:$B$346="Полюс Красноярск")*('Парк (SAP)'!$D$11:$D$346="NTE")*('Парк (SAP)'!$H$11:$H$346<=EOMONTH(A5,0))*('Парк (SAP)'!$J$11:$J$346>=A5)) -> 2 | D5: =SUMPRODUCT(('Парк (SAP)'!$B$11:$B$346="Полюс Красноярск")*('Парк (SAP)'!$D$11:$D$346="TR100")*('Парк (SAP)'!$H$11:$H$346<=EOMONTH(A5,0))*('Парк (SAP)'!$J$11:$J$346>=A5)) -> 0 | E5: =SUMPRODUCT(('Парк (SAP)'!$B$11:$B$346="Полюс Сухой Лог")*('Парк (SAP)'!$D$11:$D$346="NTE")*('Парк (SAP)'!$H$11:$H$346<=EOMONTH(A5,0))*('Парк (SAP)'!$J$11:$J$346>=A5)) -> 0 | F5: =SUMPRODUCT(('Парк (SAP)'!$B$11:$B$346="Полюс Сухой Лог")*('Парк (SAP)'!$D$11:$D$346="TR100")*('Парк (SAP)'!$H$11:$H$346<=EOMONTH(A5,0))*('Парк (SAP)'!$J$11:$J$346>=A5)) -> 0 | G5: =SUMPRODUCT(('Парк (SAP)'!$B$11:$B$346="Полюс Магадан")*('Парк (SAP)'!$D$11:$D$346="NTE")*('Парк (SAP)'!$H$11:$H$346<=EOMONTH(A5,0))*('Парк (SAP)'!$J$11:$J$346>=A5)) -> 6 | H5: =SUMPRODUCT(('Парк (SAP)'!$B$11:$B$346="Полюс Магадан")*('Парк (SAP)'!$D$11:$D$346="TR100")*('Парк (SAP)'!$H$11:$H$346<=EOMONTH(A5,0))*('Парк (SAP)'!$J$11:$J$346>=A5)) -> 0 | I5: =SUMPRODUCT(('Парк (SAP)'!$B$11:$B$346="Полюс Алдан")*('Парк (SAP)'!$D$11:$D$346="TR100")*('Парк (SAP)'!$H$11:$H$346<=EOMONTH(A5,0))*('Парк (SAP)'!$J$11:$J$346>=A5)) -> 1 | J5: =SUM(C5:I5) -> 9
A6: 45352 | B6: =YEAR(A6) -> 2024 | C6: =SUMPRODUCT(('Парк (SAP)'!$B$11:$B$346="Полюс Красноярск")*('Парк (SAP)'!$D$11:$D$346="NTE")*('Парк (SAP)'!$H$11:$H$346<=EOMONTH(A6,0))*('Парк (SAP)'!$J$11:$J$346>=A6)) -> 7 | D6: =SUMPRODUCT(('Парк (SAP)'!$B$11:$B$346="Полюс Красноярск")*('Парк (SAP)'!$D$11:$D$346="TR100")*('Парк (SAP)'!$H$11:$H$346<=EOMONTH(A6,0))*('Парк (SAP)'!$J$11:$J$346>=A6)) -> 0 | E6: =SUMPRODUCT(('Парк (SAP)'!$B$11:$B$346="Полюс Сухой Лог")*('Парк (SAP)'!$D$11:$D$346="NTE")*('Парк (SAP)'!$H$11:$H$346<=EOMONTH(A6,0))*('Парк (SAP)'!$J$11:$J$346>=A6)) -> 0 | F6: =SUMPRODUCT(('Парк (SAP)'!$B$11:$B$346="Полюс Сухой Лог")*('Парк (SAP)'!$D$11:$D$346="TR100")*('Парк (SAP)'!$H$11:$H$346<=EOMONTH(A6,0))*('Парк (SAP)'!$J$11:$J$346>=A6)) -> 0 | G6: =SUMPRODUCT(('Парк (SAP)'!$B$11:$B$346="Полюс Магадан")*('Парк (SAP)'!$D$11:$D$346="NTE")*('Парк (SAP)'!$H$11:$H$346<=EOMONTH(A6,0))*('Парк (SAP)'!$J$11:$J$346>=A6)) -> 11 | H6: =SUMPRODUCT(('Парк (SAP)'!$B$11:$B$346="Полюс Магадан")*('Парк (SAP)'!$D$11:$D$346="TR100")*('Парк (SAP)'!$H$11:$H$346<=EOMONTH(A6,0))*('Парк (SAP)'!$J$11:$J$346>=A6)) -> 0 | I6: =SUMPRODUCT(('Парк (SAP)'!$B$11:$B$346="Полюс Алдан")*('Парк (SAP)'!$D$11:$D$346="TR100")*('Парк (SAP)'!$H$11:$H$346<=EOMONTH(A6,0))*('Парк (SAP)'!$J$11:$J$346>=A6)) -> 1 | J6: =SUM(C6:I6) -> 19
A7: 45383 | B7: =YEAR(A7) -> 2024 | C7: =SUMPRODUCT(('Парк (SAP)'!$B$11:$B$346="Полюс Красноярск")*('Парк (SAP)'!$D$11:$D$346="NTE")*('Парк (SAP)'!$H$11:$H$346<=EOMONTH(A7,0))*('Парк (SAP)'!$J$11:$J$346>=A7)) -> 12 | D7: =SUMPRODUCT(('Парк (SAP)'!$B$11:$B$346="Полюс Красноярск")*('Парк (SAP)'!$D$11:$D$346="TR100")*('Парк (SAP)'!$H$11:$H$346<=EOMONTH(A7,0))*('Парк (SAP)'!$J$11:$J$346>=A7)) -> 0 | E7: =SUMPRODUCT(('Парк (SAP)'!$B$11:$B$346="Полюс Сухой Лог")*('Парк (SAP)'!$D$11:$D$346="NTE")*('Парк (SAP)'!$H$11:$H$346<=EOMONTH(A7,0))*('Парк (SAP)'!$J$11:$J$346>=A7)) -> 0 | F7: =SUMPRODUCT(('Парк (SAP)'!$B$11:$B$346="Полюс Сухой Лог")*('Парк (SAP)'!$D$11:$D$346="TR100")*('Парк (SAP)'!$H$11:$H$346<=EOMONTH(A7,0))*('Парк (SAP)'!$J$11:$J$346>=A7)) -> 0 | G7: =SUMPRODUCT(('Парк (SAP)'!$B$11:$B$346="Полюс Магадан")*('Парк (SAP)'!$D$11:$D$346="NTE")*('Парк (SAP)'!$H$11:$H$346<=EOMONTH(A7,0))*('Парк (SAP)'!$J$11:$J$346>=A7)) -> 16 | H7: =SUMPRODUCT(('Парк (SAP)'!$B$11:$B$346="Полюс Магадан")*('Парк (SAP)'!$D$11:$D$346="TR100")*('Парк (SAP)'!$H$11:$H$346<=EOMONTH(A7,0))*('Парк (SAP)'!$J$11:$J$346>=A7)) -> 0 | I7: =SUMPRODUCT(('Парк (SAP)'!$B$11:$B$346="Полюс Алдан")*('Парк (SAP)'!$D$11:$D$346="TR100")*('Парк (SAP)'!$H$11:$H$346<=EOMONTH(A7,0))*('Парк (SAP)'!$J$11:$J$346>=A7)) -> 1 | J7: =SUM(C7:I7) -> 29
A8: 45413 | B8: =YEAR(A8) -> 2024 | C8: =SUMPRODUCT(('Парк (SAP)'!$B$11:$B$346="Полюс Красноярск")*('Парк (SAP)'!$D$11:$D$346="NTE")*('Парк (SAP)'!$H$11:$H$346<=EOMONTH(A8,0))*('Парк (SAP)'!$J$11:$J$346>=A8)) -> 17 | D8: =SUMPRODUCT(('Парк (SAP)'!$B$11:$B$346="Полюс Красноярск")*('Парк (SAP)'!$D$11:$D$346="TR100")*('Парк (SAP)'!$H$11:$H$346<=EOMONTH(A8,0))*('Парк (SAP)'!$J$11:$J$346>=A8)) -> 0 | E8: =SUMPRODUCT(('Парк (SAP)'!$B$11:$B$346="Полюс Сухой Лог")*('Парк (SAP)'!$D$11:$D$346="NTE")*('Парк (SAP)'!$H$11:$H$346<=EOMONTH(A8,0))*('Парк (SAP)'!$J$11:$J$346>=A8)) -> 0 | F8: =SUMPRODUCT(('Парк (SAP)'!$B$11:$B$346="Полюс Сухой Лог")*('Парк (SAP)'!$D$11:$D$346="TR100")*('Парк (SAP)'!$H$11:$H$346<=EOMONTH(A8,0))*('Парк (SAP)'!$J$11:$J$346>=A8)) -> 2 | G8: =SUMPRODUCT(('Парк (SAP)'!$B$11:$B$346="Полюс Магадан")*('Парк (SAP)'!$D$11:$D$346="NTE")*('Парк (SAP)'!$H$11:$H$346<=EOMONTH(A8,0))*('Парк (SAP)'!$J$11:$J$346>=A8)) -> 20 | H8: =SUMPRODUCT(('Парк (SAP)'!$B$11:$B$346="Полюс Магадан")*('Парк (SAP)'!$D$11:$D$346="TR100")*('Парк (SAP)'!$H$11:$H$346<=EOMONTH(A8,0))*('Парк (SAP)'!$J$11:$J$346>=A8)) -> 0 | I8: =SUMPRODUCT(('Парк (SAP)'!$B$11:$B$346="Полюс Алдан")*('Парк (SAP)'!$D$11:$D$346="TR100")*('Парк (SAP)'!$H$11:$H$346<=EOMONTH(A8,0))*('Парк (SAP)'!$J$11:$J$346>=A8)) -> 1 | J8: =SUM(C8:I8) -> 40
A9: 45444 | B9: =YEAR(A9) -> 2024 | C9: =SUMPRODUCT(('Парк (SAP)'!$B$11:$B$346="Полюс Красноярск")*('Парк (SAP)'!$D$11:$D$346="NTE")*('Парк (SAP)'!$H$11:$H$346<=EOMONTH(A9,0))*('Парк (SAP)'!$J$11:$J$346>=A9)) -> 22 | D9: =SUMPRODUCT(('Парк (SAP)'!$B$11:$B$346="Полюс Красноярск")*('Парк (SAP)'!$D$11:$D$346="TR100")*('Парк (SAP)'!$H$11:$H$346<=EOMONTH(A9,0))*('Парк (SAP)'!$J$11:$J$346>=A9)) -> 0 | E9: =SUMPRODUCT(('Парк (SAP)'!$B$11:$B$346="Полюс Сухой Лог")*('Парк (SAP)'!$D$11:$D$346="NTE")*('Парк (SAP)'!$H$11:$H$346<=EOMONTH(A9,0))*('Парк (SAP)'!$J$11:$J$346>=A9)) -> 0 | F9: =SUMPRODUCT(('Парк (SAP)'!$B$11:$B$346="Полюс Сухой Лог")*('Парк (SAP)'!$D$11:$D$346="TR100")*('Парк (SAP)'!$H$11:$H$346<=EOMONTH(A9,0))*('Парк (SAP)'!$J$11:$J$346>=A9)) -> 2 | G9: =SUMPRODUCT(('Парк (SAP)'!$B$11:$B$346="Полюс Магадан")*('Парк (SAP)'!$D$11:$D$346="NTE")*('Парк (SAP)'!$H$11:$H$346<=EOMONTH(A9,0))*('Парк (SAP)'!$J$11:$J$346>=A9)) -> 20 | H9: =SUMPRODUCT(('Парк (SAP)'!$B$11:$B$346="Полюс Магадан")*('Парк (SAP)'!$D$11:$D$346="TR100")*('Парк (SAP)'!$H$11:$H$346<=EOMONTH(A9,0))*('Парк (SAP)'!$J$11:$J$346>=A9)) -> 0 | I9: =SUMPRODUCT(('Парк (SAP)'!$B$11:$B$346="Полюс Алдан")*('Парк (SAP)'!$D$11:$D$346="TR100")*('Парк (SAP)'!$H$11:$H$346<=EOMONTH(A9,0))*('Парк (SAP)'!$J$11:$J$346>=A9)) -> 1 | J9: =SUM(C9:I9) -> 45
A10: 45474 | B10: =YEAR(A10) -> 2024 | C10: =SUMPRODUCT(('Парк (SAP)'!$B$11:$B$346="Полюс Красноярск")*('Парк (SAP)'!$D$11:$D$346="NTE")*('Парк (SAP)'!$H$11:$H$346<=EOMONTH(A10,0))*('Парк (SAP)'!$J$11:$J$346>=A10)) -> 24 | D10: =SUMPRODUCT(('Парк (SAP)'!$B$11:$B$346="Полюс Красноярск")*('Парк (SAP)'!$D$11:$D$346="TR100")*('Парк (SAP)'!$H$11:$H$346<=EOMONTH(A10,0))*('Парк (SAP)'!$J$11:$J$346>=A10)) -> 0 | E10: =SUMPRODUCT(('Парк (SAP)'!$B$11:$B$346="Полюс Сухой Лог")*('Парк (SAP)'!$D$11:$D$346="NTE")*('Парк (SAP)'!$H$11:$H$346<=EOMONTH(A10,0))*('Парк (SAP)'!$J$11:$J$346>=A10)) -> 0 | F10: =SUMPRODUCT(('Парк (SAP)'!$B$11:$B$346="Полюс Сухой Лог")*('Парк (SAP)'!$D$11:$D$346="TR100")*('Парк (SAP)'!$H$11:$H$346<=EOMONTH(A10,0))*('Парк (SAP)'!$J$11:$J$346>=A10)) -> 9 | G10: =SUMPRODUCT(('Парк (SAP)'!$B$11:$B$346="Полюс Магадан")*('Парк (SAP)'!$D$11:$D$346="NTE")*('Парк (SAP)'!$H$11:$H$346<=EOMONTH(A10,0))*('Парк (SAP)'!$J$11:$J$346>=A10)) -> 20 | H10: =SUMPRODUCT(('Парк (SAP)'!$B$11:$B$346="Полюс Магадан")*('Парк (SAP)'!$D$11:$D$346="TR100")*('Парк (SAP)'!$H$11:$H$346<=EOMONTH(A10,0))*('Парк (SAP)'!$J$11:$J$346>=A10)) -> 0 | I10: =SUMPRODUCT(('Парк (SAP)'!$B$11:$B$346="Полюс Алдан")*('Парк (SAP)'!$D$11:$D$346="TR100")*('Парк (SAP)'!$H$11:$H$346<=EOMONTH(A10,0))*('Парк (SAP)'!$J$11:$J$346>=A10)) -> 1 | J10: =SUM(C10:I10) -> 54
A11: 45505 | B11: =YEAR(A11) -> 2024 | C11: =SUMPRODUCT(('Парк (SAP)'!$B$11:$B$346="Полюс Красноярск")*('Парк (SAP)'!$D$11:$D$346="NTE")*('Парк (SAP)'!$H$11:$H$346<=EOMONTH(A11,0))*('Парк (SAP)'!$J$11:$J$346>=A11)) -> 26 | D11: =SUMPRODUCT(('Парк (SAP)'!$B$11:$B$346="Полюс Красноярск")*('Парк (SAP)'!$D$11:$D$346="TR100")*('Парк (SAP)'!$H$11:$H$346<=EOMONTH(A11,0))*('Парк (SAP)'!$J$11:$J$346>=A11)) -> 0 | E11: =SUMPRODUCT(('Парк (SAP)'!$B$11:$B$346="Полюс Сухой Лог")*('Парк (SAP)'!$D$11:$D$346="NTE")*('Парк (SAP)'!$H$11:$H$346<=EOMONTH(A11,0))*('Парк (SAP)'!$J$11:$J$346>=A11)) -> 0 | F11: =SUMPRODUCT(('Парк (SAP)'!$B$11:$B$346="Полюс Сухой Лог")*('Парк (SAP)'!$D$11:$D$346="TR100")*('Парк (SAP)'!$H$11:$H$346<=EOMONTH(A11,0))*('Парк (SAP)'!$J$11:$J$346>=A11)) -> 9 | G11: =SUMPRODUCT(('Парк (SAP)'!$B$11:$B$346="Полюс Магадан")*('Парк (SAP)'!$D$11:$D$346="NTE")*('Парк (SAP)'!$H$11:$H$346<=EOMONTH(A11,0))*('Парк (SAP)'!$J$11:$J$346>=A11)) -> 20 | H11: =SUMPRODUCT(('Парк (SAP)'!$B$11:$B$346="Полюс Магадан")*('Парк (SAP)'!$D$11:$D$346="TR100")*('Парк (SAP)'!$H$11:$H$346<=EOMONTH(A11,0))*('Парк (SAP)'!$J$11:$J$346>=A11)) -> 0 | I11: =SUMPRODUCT(('Парк (SAP)'!$B$11:$B$346="Полюс Алдан")*('Парк (SAP)'!$D$11:$D$346="TR100")*('Парк (SAP)'!$H$11:$H$346<=EOMONTH(A11,0))*('Парк (SAP)'!$J$11:$J$346>=A11)) -> 1 | J11: =SUM(C11:I11) -> 56
A12: 45536 | B12: =YEAR(A12) -> 2024 | C12: =SUMPRODUCT(('Парк (SAP)'!$B$11:$B$346="Полюс Красноярск")*('Парк (SAP)'!$D$11:$D$346="NTE")*('Парк (SAP)'!$H$11:$H$346<=EOMONTH(A12,0))*('Парк (SAP)'!$J$11:$J$346>=A12)) -> 30 | D12: =SUMPRODUCT(('Парк (SAP)'!$B$11:$B$346="Полюс Красноярск")*('Парк (SAP)'!$D$11:$D$346="TR100")*('Парк (SAP)'!$H$11:$H$346<=EOMONTH(A12,0))*('Парк (SAP)'!$J$11:$J$346>=A12)) -> 0 | E12: =SUMPRODUCT(('Парк (SAP)'!$B$11:$B$346="Полюс Сухой Лог")*('Парк (SAP)'!$D$11:$D$346="NTE")*('Парк (SAP)'!$H$11:$H$346<=EOMONTH(A12,0))*('Парк (SAP)'!$J$11:$J$346>=A12)) -> 0 | F12: =SUMPRODUCT(('Парк (SAP)'!$B$11:$B$346="Полюс Сухой Лог")*('Парк (SAP)'!$D$11:$D$346="TR100")*('Парк (SAP)'!$H$11:$H$346<=EOMONTH(A12,0))*('Парк (SAP)'!$J$11:$J$346>=A12)) -> 9 | G12: =SUMPRODUCT(('Парк (SAP)'!$B$11:$B$346="Полюс Магадан")*('Парк (SAP)'!$D$11:$D$346="NTE")*('Парк (SAP)'!$H$11:$H$346<=EOMONTH(A12,0))*('Парк (SAP)'!$J$11:$J$346>=A12)) -> 20 | H12: =SUMPRODUCT(('Парк (SAP)'!$B$11:$B$346="Полюс Магадан")*('Парк (SAP)'!$D$11:$D$346="TR100")*('Парк (SAP)'!$H$11:$H$346<=EOMONTH(A12,0))*('Парк (SAP)'!$J$11:$J$346>=A12)) -> 0 | I12: =SUMPRODUCT(('Парк (SAP)'!$B$11:$B$346="Полюс Алдан")*('Парк (SAP)'!$D$11:$D$346="TR100")*('Парк (SAP)'!$H$11:$H$346<=EOMONTH(A12,0))*('Парк (SAP)'!$J$11:$J$346>=A12)) -> 1 | J12: =SUM(C12:I12) -> 60
A13: 45566 | B13: =YEAR(A13) -> 2024 | C13: =SUMPRODUCT(('Парк (SAP)'!$B$11:$B$346="Полюс Красноярск")*('Парк (SAP)'!$D$11:$D$346="NTE")*('Парк (SAP)'!$H$11:$H$346<=EOMONTH(A13,0))*('Парк (SAP)'!$J$11:$J$346>=A13)) -> 32 | D13: =SUMPRODUCT(('Парк (SAP)'!$B$11:$B$346="Полюс Красноярск")*('Парк (SAP)'!$D$11:$D$346="TR100")*('Парк (SAP)'!$H$11:$H$346<=EOMONTH(A13,0))*('Парк (SAP)'!$J$11:$J$346>=A13)) -> 0 | E13: =SUMPRODUCT(('Парк (SAP)'!$B$11:$B$346="Полюс Сухой Лог")*('Парк (SAP)'!$D$11:$D$346="NTE")*('Парк (SAP)'!$H$11:$H$346<=EOMONTH(A13,0))*('Парк (SAP)'!$J$11:$J$346>=A13)) -> 0 | F13: =SUMPRODUCT(('Парк (SAP)'!$B$11:$B$346="Полюс Сухой Лог")*('Парк (SAP)'!$D$11:$D$346="TR100")*('Парк (SAP)'!$H$11:$H$346<=EOMONTH(A13,0))*('Парк (SAP)'!$J$11:$J$346>=A13)) -> 9 | G13: =SUMPRODUCT(('Парк (SAP)'!$B$11:$B$346="Полюс Магадан")*('Парк (SAP)'!$D$11:$D$346="NTE")*('Парк (SAP)'!$H$11:$H$346<=EOMONTH(A13,0))*('Парк (SAP)'!$J$11:$J$346>=A13)) -> 20 | H13: =SUMPRODUCT(('Парк (SAP)'!$B$11:$B$346="Полюс Магадан")*('Парк (SAP)'!$D$11:$D$346="TR100")*('Парк (SAP)'!$H$11:$H$346<=EOMONTH(A13,0))*('Парк (SAP)'!$J$11:$J$346>=A13)) -> 0 | I13: =SUMPRODUCT(('Парк (SAP)'!$B$11:$B$346="Полюс Алдан")*('Парк (SAP)'!$D$11:$D$346="TR100")*('Парк (SAP)'!$H$11:$H$346<=EOMONTH(A13,0))*('Парк (SAP)'!$J$11:$J$346>=A13)) -> 1 | J13: =SUM(C13:I13) -> 62
A14: 45597 | B14: =YEAR(A14) -> 2024 | C14: =SUMPRODUCT(('Парк (SAP)'!$B$11:$B$346="Полюс Красноярск")*('Парк (SAP)'!$D$11:$D$346="NTE")*('Парк (SAP)'!$H$11:$H$346<=EOMONTH(A14,0))*('Парк (SAP)'!$J$11:$J$346>=A14)) -> 32 | D14: =SUMPRODUCT(('Парк (SAP)'!$B$11:$B$346="Полюс Красноярск")*('Парк (SAP)'!$D$11:$D$346="TR100")*('Парк (SAP)'!$H$11:$H$346<=EOMONTH(A14,0))*('Парк (SAP)'!$J$11:$J$346>=A14)) -> 0 | E14: =SUMPRODUCT(('Парк (SAP)'!$B$11:$B$346="Полюс Сухой Лог")*('Парк (SAP)'!$D$11:$D$346="NTE")*('Парк (SAP)'!$H$11:$H$346<=EOMONTH(A14,0))*('Парк (SAP)'!$J$11:$J$346>=A14)) -> 0 | F14: =SUMPRODUCT(('Парк (SAP)'!$B$11:$B$346="Полюс Сухой Лог")*('Парк (SAP)'!$D$11:$D$346="TR100")*('Парк (SAP)'!$H$11:$H$346<=EOMONTH(A14,0))*('Парк (SAP)'!$J$11:$J$346>=A14)) -> 9 | G14: =SUMPRODUCT(('Парк (SAP)'!$B$11:$B$346="Полюс Магадан")*('Парк (SAP)'!$D$11:$D$346="NTE")*('Парк (SAP)'!$H$11:$H$346<=EOMONTH(A14,0))*('Парк (SAP)'!$J$11:$J$346>=A14)) -> 20 | H14: =SUMPRODUCT(('Парк (SAP)'!$B$11:$B$346="Полюс Магадан")*('Парк (SAP)'!$D$11:$D$346="TR100")*('Парк (SAP)'!$H$11:$H$346<=EOMONTH(A14,0))*('Парк (SAP)'!$J$11:$J$346>=A14)) -> 0 | I14: =SUMPRODUCT(('Парк (SAP)'!$B$11:$B$346="Полюс Алдан")*('Парк (SAP)'!$D$11:$D$346="TR100")*('Парк (SAP)'!$H$11:$H$346<=EOMONTH(A14,0))*('Парк (SAP)'!$J$11:$J$346>=A14)) -> 1 | J14: =SUM(C14:I14) -> 62
A15: 45627 | B15: =YEAR(A15) -> 2024 | C15: =SUMPRODUCT(('Парк (SAP)'!$B$11:$B$346="Полюс Красноярск")*('Парк (SAP)'!$D$11:$D$346="NTE")*('Парк (SAP)'!$H$11:$H$346<=EOMONTH(A15,0))*('Парк (SAP)'!$J$11:$J$346>=A15)) -> 36 | D15: =SUMPRODUCT(('Парк (SAP)'!$B$11:$B$346="Полюс Красноярск")*('Парк (SAP)'!$D$11:$D$346="TR100")*('Парк (SAP)'!$H$11:$H$346<=EOMONTH(A15,0))*('Парк (SAP)'!$J$11:$J$346>=A15)) -> 0 | E15: =SUMPRODUCT(('Парк (SAP)'!$B$11:$B$346="Полюс Сухой Лог")*('Парк (SAP)'!$D$11:$D$346="NTE")*('Парк (SAP)'!$H$11:$H$346<=EOMONTH(A15,0))*('Парк (SAP)'!$J$11:$J$346>=A15)) -> 0 | F15: =SUMPRODUCT(('Парк (SAP)'!$B$11:$B$346="Полюс Сухой Лог")*('Парк (SAP)'!$D$11:$D$346="TR100")*('Парк (SAP)'!$H$11:$H$346<=EOMONTH(A15,0))*('Парк (SAP)'!$J$11:$J$346>=A15)) -> 9 | G15: =SUMPRODUCT(('Парк (SAP)'!$B$11:$B$346="Полюс Магадан")*('Парк (SAP)'!$D$11:$D$346="NTE")*('Парк (SAP)'!$H$11:$H$346<=EOMONTH(A15,0))*('Парк (SAP)'!$J$11:$J$346>=A15)) -> 22 | H15: =SUMPRODUCT(('Парк (SAP)'!$B$11:$B$346="Полюс Магадан")*('Парк (SAP)'!$D$11:$D$346="TR100")*('Парк (SAP)'!$H$11:$H$346<=EOMONTH(A15,0))*('Парк (SAP)'!$J$11:$J$346>=A15)) -> 0 | I15: =SUMPRODUCT(('Парк (SAP)'!$B$11:$B$346="Полюс Алдан")*('Парк (SAP)'!$D$11:$D$346="TR100")*('Парк (SAP)'!$H$11:$H$346<=EOMONTH(A15,0))*('Парк (SAP)'!$J$11:$J$346>=A15)) -> 1 | J15: =SUM(C15:I15) -> 68
A16: 45658 | B16: =YEAR(A16) -> 2025 | C16: =SUMPRODUCT(('Парк (SAP)'!$B$11:$B$346="Полюс Красноярск")*('Парк (SAP)'!$D$11:$D$346="NTE")*('Парк (SAP)'!$H$11:$H$346<=EOMONTH(A16,0))*('Парк (SAP)'!$J$11:$J$346>=A16)) -> 40 | D16: =SUMPRODUCT(('Парк (SAP)'!$B$11:$B$346="Полюс Красноярск")*('Парк (SAP)'!$D$11:$D$346="TR100")*('Парк (SAP)'!$H$11:$H$346<=EOMONTH(A16,0))*('Парк (SAP)'!$J$11:$J$346>=A16)) -> 0 | E16: =SUMPRODUCT(('Парк (SAP)'!$B$11:$B$346="Полюс Сухой Лог")*('Парк (SAP)'!$D$11:$D$346="NTE")*('Парк (SAP)'!$H$11:$H$346<=EOMONTH(A16,0))*('Парк (SAP)'!$J$11:$J$346>=A16)) -> 0 | F16: =SUMPRODUCT(('Парк (SAP)'!$B$11:$B$346="Полюс Сухой Лог")*('Парк (SAP)'!$D$11:$D$346="TR100")*('Парк (SAP)'!$H$11:$H$346<=EOMONTH(A16,0))*('Парк (SAP)'!$J$11:$J$346>=A16)) -> 9 | G16: =SUMPRODUCT(('Парк (SAP)'!$B$11:$B$346="Полюс Магадан")*('Парк (SAP)'!$D$11:$D$346="NTE")*('Парк (SAP)'!$H$11:$H$346<=EOMONTH(A16,0))*('Парк (SAP)'!$J$11:$J$346>=A16)) -> 28 | H16: =SUMPRODUCT(('Парк (SAP)'!$B$11:$B$346="Полюс Магадан")*('Парк (SAP)'!$D$11:$D$346="TR100")*('Парк (SAP)'!$H$11:$H$346<=EOMONTH(A16,0))*('Парк (SAP)'!$J$11:$J$346>=A16)) -> 0 | I16: =SUMPRODUCT(('Парк (SAP)'!$B$11:$B$346="Полюс Алдан")*('Парк (SAP)'!$D$11:$D$346="TR100")*('Парк (SAP)'!$H$11:$H$346<=EOMONTH(A16,0))*('Парк (SAP)'!$J$11:$J$346>=A16)) -> 1 | J16: =SUM(C16:I16) -> 78
... A93: 48000 | B93: =YEAR(A93) -> 2031 | C93: =SUMPRODUCT(('Парк (SAP)'!$B$11:$B$346="Полюс Красноярск")*('Парк (SAP)'!$D$11:$D$346="NTE")*('Парк (SAP)'!$H$11:$H$346<=EOMONTH(A93,0))*('Парк (SAP)'!$J$11:$J$346>=A93)) -> 0 | D93: =SUMPRODUCT(('Парк (SAP)'!$B$11:$B$346="Полюс Красноярск")*('Парк (SAP)'!$D$11:$D$346="TR100")*('Парк (SAP)'!$H$11:$H$346<=EOMONTH(A93,0))*('Парк (SAP)'!$J$11:$J$346>=A93)) -> 0 | E93: =SUMPRODUCT(('Парк (SAP)'!$B$11:$B$346="Полюс Сухой Лог")*('Парк (SAP)'!$D$11:$D$346="NTE")*('Парк (SAP)'!$H$11:$H$346<=EOMONTH(A93,0))*('Парк (SAP)'!$J$11:$J$346>=A93)) -> 0 | F93: =SUMPRODUCT(('Парк (SAP)'!$B$11:$B$346="Полюс Сухой Лог")*('Парк (SAP)'!$D$11:$D$346="TR100")*('Парк (SAP)'!$H$11:$H$346<=EOMONTH(A93,0))*('Парк (SAP)'!$J$11:$J$346>=A93)) -> 0 | G93: =SUMPRODUCT(('Парк (SAP)'!$B$11:$B$346="Полюс Магадан")*('Парк (SAP)'!$D$11:$D$346="NTE")*('Парк (SAP)'!$H$11:$H$346<=EOMONTH(A93,0))*('Парк (SAP)'!$J$11:$J$346>=A93)) -> 0 | H93: =SUMPRODUCT(('Парк (SAP)'!$B$11:$B$346="Полюс Магадан")*('Парк (SAP)'!$D$11:$D$346="TR100")*('Парк (SAP)'!$H$11:$H$346<=EOMONTH(A93,0))*('Парк (SAP)'!$J$11:$J$346>=A93)) -> 0 | I93: =SUMPRODUCT(('Парк (SAP)'!$B$11:$B$346="Полюс Алдан")*('Парк (SAP)'!$D$11:$D$346="TR100")*('Парк (SAP)'!$H$11:$H$346<=EOMONTH(A93,0))*('Парк (SAP)'!$J$11:$J$346>=A93)) -> 0 | J93: =SUM(C93:I93) -> 0
A95: ПИК | C95: =MAX(C5:C93) -> 53 | D95: =MAX(D5:D93) -> 22 | E95: =MAX(E5:E93) -> 76 | F95: =MAX(F5:F93) -> 9 | G95: =MAX(G5:G93) -> 34 | H95: =MAX(H5:H93) -> 7 | I95: =MAX(I5:I93) -> 28 | J95: =MAX(J5:J93) -> 151

Sheet ОФ - расчёт по месяцам
A1: ОФ — РАСЧЁТ ПО МЕСЯЦАМ (ПО ПЛОЩАДКАМ И МОДЕЛЯМ)
A2: Отдельный помесячный расчёт (аналог отчёта Power BI): ввод в эксплуатацию, парк на гарантии, выход из гарантии — по месяцам, с фильтром по площадке и марке. Срок гарантии здесь — единый параметр (упрощение для этого расчёта); детальный расчёт с раздельным сроком NTE/TR100 — на листе «Парк (SAP)».
A4: Площадка (БЕ) | C4: (Все) | E4: Марка | G4: (Все)
A5: Срок гарантии для этого расчёта, мес | C5: 24
A7: Месяц | B7: Введено на гарантию | C7: Машин на гарантии | D7: Сошло с гарантии | E7: Машин в эксплуатации | F7: Сошло с гарантии (накопитель)
A8: 45292 | B8: =SUMPRODUCT(((YEAR('Парк (SAP)'!$H$11:$H$346)*12+MONTH('Парк (SAP)'!$H$11:$H$346)-1)=(YEAR($A8)*12+MONTH($A8)-1))*((($C4="(Все)")+('Парк (SAP)'!$B$11:$B$346=$C4)>0))*((($G4="(Все)")+('Парк (SAP)'!$C$11:$C$346=$G4)>0))) -> 0 | C8: =E8 -> 0 | D8: =SUMPRODUCT((((YEAR('Парк (SAP)'!$H$11:$H$346)*12+MONTH('Парк (SAP)'!$H$11:$H$346)-1)+$C5)=(YEAR($A8)*12+MONTH($A8)-1))*((($C4="(Все)")+('Парк (SAP)'!$B$11:$B$346=$C4)>0))*((($G4="(Все)")+('Парк (SAP)'!$C$11:$C$346=$G4)>0))) -> 0 | E8: =SUMPRODUCT(((YEAR('Парк (SAP)'!$H$11:$H$346)*12+MONTH('Парк (SAP)'!$H$11:$H$346)-1)<=(YEAR($A8)*12+MONTH($A8)-1))*((($C4="(Все)")+('Парк (SAP)'!$B$11:$B$346=$C4)>0))*((($G4="(Все)")+('Парк (SAP)'!$C$11:$C$346=$G4)>0))) -> 0 | F8: =SUMPRODUCT((((YEAR('Парк (SAP)'!$H$11:$H$346)*12+MONTH('Парк (SAP)'!$H$11:$H$346)-1)+$C5)<=(YEAR($A8)*12+MONTH($A8)-1))*((($C4="(Все)")+('Парк (SAP)'!$B$11:$B$346=$C4)>0))*((($G4="(Все)")+('Парк (SAP)'!$C$11:$C$346=$G4)>0))) -> 0
A9: 45323 | B9: =SUMPRODUCT(((YEAR('Парк (SAP)'!$H$11:$H$346)*12+MONTH('Парк (SAP)'!$H$11:$H$346)-1)=(YEAR($A9)*12+MONTH($A9)-1))*((($C4="(Все)")+('Парк (SAP)'!$B$11:$B$346=$C4)>0))*((($G4="(Все)")+('Парк (SAP)'!$C$11:$C$346=$G4)>0))) -> 9 | C9: =E9-F8 -> 9 | D9: =SUMPRODUCT((((YEAR('Парк (SAP)'!$H$11:$H$346)*12+MONTH('Парк (SAP)'!$H$11:$H$346)-1)+$C5)=(YEAR($A9)*12+MONTH($A9)-1))*((($C4="(Все)")+('Парк (SAP)'!$B$11:$B$346=$C4)>0))*((($G4="(Все)")+('Парк (SAP)'!$C$11:$C$346=$G4)>0))) -> 0 | E9: =SUMPRODUCT(((YEAR('Парк (SAP)'!$H$11:$H$346)*12+MONTH('Парк (SAP)'!$H$11:$H$346)-1)<=(YEAR($A9)*12+MONTH($A9)-1))*((($C4="(Все)")+('Парк (SAP)'!$B$11:$B$346=$C4)>0))*((($G4="(Все)")+('Парк (SAP)'!$C$11:$C$346=$G4)>0))) -> 9 | F9: =SUMPRODUCT((((YEAR('Парк (SAP)'!$H$11:$H$346)*12+MONTH('Парк (SAP)'!$H$11:$H$346)-1)+$C5)<=(YEAR($A9)*12+MONTH($A9)-1))*((($C4="(Все)")+('Парк (SAP)'!$B$11:$B$346=$C4)>0))*((($G4="(Все)")+('Парк (SAP)'!$C$11:$C$346=$G4)>0))) -> 0
A10: 45352 | B10: =SUMPRODUCT(((YEAR('Парк (SAP)'!$H$11:$H$346)*12+MONTH('Парк (SAP)'!$H$11:$H$346)-1)=(YEAR($A10)*12+MONTH($A10)-1))*((($C4="(Все)")+('Парк (SAP)'!$B$11:$B$346=$C4)>0))*((($G4="(Все)")+('Парк (SAP)'!$C$11:$C$346=$G4)>0))) -> 10 | C10: =E10-F9 -> 19 | D10: =SUMPRODUCT((((YEAR('Парк (SAP)'!$H$11:$H$346)*12+MONTH('Парк (SAP)'!$H$11:$H$346)-1)+$C5)=(YEAR($A10)*12+MONTH($A10)-1))*((($C4="(Все)")+('Парк (SAP)'!$B$11:$B$346=$C4)>0))*((($G4="(Все)")+('Парк (SAP)'!$C$11:$C$346=$G4)>0))) -> 0 | E10: =SUMPRODUCT(((YEAR('Парк (SAP)'!$H$11:$H$346)*12+MONTH('Парк (SAP)'!$H$11:$H$346)-1)<=(YEAR($A10)*12+MONTH($A10)-1))*((($C4="(Все)")+('Парк (SAP)'!$B$11:$B$346=$C4)>0))*((($G4="(Все)")+('Парк (SAP)'!$C$11:$C$346=$G4)>0))) -> 19 | F10: =SUMPRODUCT((((YEAR('Парк (SAP)'!$H$11:$H$346)*12+MONTH('Парк (SAP)'!$H$11:$H$346)-1)+$C5)<=(YEAR($A10)*12+MONTH($A10)-1))*((($C4="(Все)")+('Парк (SAP)'!$B$11:$B$346=$C4)>0))*((($G4="(Все)")+('Парк (SAP)'!$C$11:$C$346=$G4)>0))) -> 0
A11: 45383 | B11: =SUMPRODUCT(((YEAR('Парк (SAP)'!$H$11:$H$346)*12+MONTH('Парк (SAP)'!$H$11:$H$346)-1)=(YEAR($A11)*12+MONTH($A11)-1))*((($C4="(Все)")+('Парк (SAP)'!$B$11:$B$346=$C4)>0))*((($G4="(Все)")+('Парк (SAP)'!$C$11:$C$346=$G4)>0))) -> 10 | C11: =E11-F10 -> 29 | D11: =SUMPRODUCT((((YEAR('Парк (SAP)'!$H$11:$H$346)*12+MONTH('Парк (SAP)'!$H$11:$H$346)-1)+$C5)=(YEAR($A11)*12+MONTH($A11)-1))*((($C4="(Все)")+('Парк (SAP)'!$B$11:$B$346=$C4)>0))*((($G4="(Все)")+('Парк (SAP)'!$C$11:$C$346=$G4)>0))) -> 0 | E11: =SUMPRODUCT(((YEAR('Парк (SAP)'!$H$11:$H$346)*12+MONTH('Парк (SAP)'!$H$11:$H$346)-1)<=(YEAR($A11)*12+MONTH($A11)-1))*((($C4="(Все)")+('Парк (SAP)'!$B$11:$B$346=$C4)>0))*((($G4="(Все)")+('Парк (SAP)'!$C$11:$C$346=$G4)>0))) -> 29 | F11: =SUMPRODUCT((((YEAR('Парк (SAP)'!$H$11:$H$346)*12+MONTH('Парк (SAP)'!$H$11:$H$346)-1)+$C5)<=(YEAR($A11)*12+MONTH($A11)-1))*((($C4="(Все)")+('Парк (SAP)'!$B$11:$B$346=$C4)>0))*((($G4="(Все)")+('Парк (SAP)'!$C$11:$C$346=$G4)>0))) -> 0
A12: 45413 | B12: =SUMPRODUCT(((YEAR('Парк (SAP)'!$H$11:$H$346)*12+MONTH('Парк (SAP)'!$H$11:$H$346)-1)=(YEAR($A12)*12+MONTH($A12)-1))*((($C4="(Все)")+('Парк (SAP)'!$B$11:$B$346=$C4)>0))*((($G4="(Все)")+('Парк (SAP)'!$C$11:$C$346=$G4)>0))) -> 11 | C12: =E12-F11 -> 40 | D12: =SUMPRODUCT((((YEAR('Парк (SAP)'!$H$11:$H$346)*12+MONTH('Парк (SAP)'!$H$11:$H$346)-1)+$C5)=(YEAR($A12)*12+MONTH($A12)-1))*((($C4="(Все)")+('Парк (SAP)'!$B$11:$B$346=$C4)>0))*((($G4="(Все)")+('Парк (SAP)'!$C$11:$C$346=$G4)>0))) -> 0 | E12: =SUMPRODUCT(((YEAR('Парк (SAP)'!$H$11:$H$346)*12+MONTH('Парк (SAP)'!$H$11:$H$346)-1)<=(YEAR($A12)*12+MONTH($A12)-1))*((($C4="(Все)")+('Парк (SAP)'!$B$11:$B$346=$C4)>0))*((($G4="(Все)")+('Парк (SAP)'!$C$11:$C$346=$G4)>0))) -> 40 | F12: =SUMPRODUCT((((YEAR('Парк (SAP)'!$H$11:$H$346)*12+MONTH('Парк (SAP)'!$H$11:$H$346)-1)+$C5)<=(YEAR($A12)*12+MONTH($A12)-1))*((($C4="(Все)")+('Парк (SAP)'!$B$11:$B$346=$C4)>0))*((($G4="(Все)")+('Парк (SAP)'!$C$11:$C$346=$G4)>0))) -> 0
A13: 45444 | B13: =SUMPRODUCT(((YEAR('Парк (SAP)'!$H$11:$H$346)*12+MONTH('Парк (SAP)'!$H$11:$H$346)-1)=(YEAR($A13)*12+MONTH($A13)-1))*((($C4="(Все)")+('Парк (SAP)'!$B$11:$B$346=$C4)>0))*((($G4="(Все)")+('Парк (SAP)'!$C$11:$C$346=$G4)>0))) -> 5 | C13: =E13-F12 -> 45 | D13: =SUMPRODUCT((((YEAR('Парк (SAP)'!$H$11:$H$346)*12+MONTH('Парк (SAP)'!$H$11:$H$346)-1)+$C5)=(YEAR($A13)*12+MONTH($A13)-1))*((($C4="(Все)")+('Парк (SAP)'!$B$11:$B$346=$C4)>0))*((($G4="(Все)")+('Парк (SAP)'!$C$11:$C$346=$G4)>0))) -> 0 | E13: =SUMPRODUCT(((YEAR('Парк (SAP)'!$H$11:$H$346)*12+MONTH('Парк (SAP)'!$H$11:$H$346)-1)<=(YEAR($A13)*12+MONTH($A13)-1))*((($C4="(Все)")+('Парк (SAP)'!$B$11:$B$346=$C4)>0))*((($G4="(Все)")+('Парк (SAP)'!$C$11:$C$346=$G4)>0))) -> 45 | F13: =SUMPRODUCT((((YEAR('Парк (SAP)'!$H$11:$H$346)*12+MONTH('Парк (SAP)'!$H$11:$H$346)-1)+$C5)<=(YEAR($A13)*12+MONTH($A13)-1))*((($C4="(Все)")+('Парк (SAP)'!$B$11:$B$346=$C4)>0))*((($G4="(Все)")+('Парк (SAP)'!$C$11:$C$346=$G4)>0))) -> 0
A14: 45474 | B14: =SUMPRODUCT(((YEAR('Парк (SAP)'!$H$11:$H$346)*12+MONTH('Парк (SAP)'!$H$11:$H$346)-1)=(YEAR($A14)*12+MONTH($A14)-1))*((($C4="(Все)")+('Парк (SAP)'!$B$11:$B$346=$C4)>0))*((($G4="(Все)")+('Парк (SAP)'!$C$11:$C$346=$G4)>0))) -> 9 | C14: =E14-F13 -> 54 | D14: =SUMPRODUCT((((YEAR('Парк (SAP)'!$H$11:$H$346)*12+MONTH('Парк (SAP)'!$H$11:$H$346)-1)+$C5)=(YEAR($A14)*12+MONTH($A14)-1))*((($C4="(Все)")+('Парк (SAP)'!$B$11:$B$346=$C4)>0))*((($G4="(Все)")+('Парк (SAP)'!$C$11:$C$346=$G4)>0))) -> 0 | E14: =SUMPRODUCT(((YEAR('Парк (SAP)'!$H$11:$H$346)*12+MONTH('Парк (SAP)'!$H$11:$H$346)-1)<=(YEAR($A14)*12+MONTH($A14)-1))*((($C4="(Все)")+('Парк (SAP)'!$B$11:$B$346=$C4)>0))*((($G4="(Все)")+('Парк (SAP)'!$C$11:$C$346=$G4)>0))) -> 54 | F14: =SUMPRODUCT((((YEAR('Парк (SAP)'!$H$11:$H$346)*12+MONTH('Парк (SAP)'!$H$11:$H$346)-1)+$C5)<=(YEAR($A14)*12+MONTH($A14)-1))*((($C4="(Все)")+('Парк (SAP)'!$B$11:$B$346=$C4)>0))*((($G4="(Все)")+('Парк (SAP)'!$C$11:$C$346=$G4)>0))) -> 0
A15: 45505 | B15: =SUMPRODUCT(((YEAR('Парк (SAP)'!$H$11:$H$346)*12+MONTH('Парк (SAP)'!$H$11:$H$346)-1)=(YEAR($A15)*12+MONTH($A15)-1))*((($C4="(Все)")+('Парк (SAP)'!$B$11:$B$346=$C4)>0))*((($G4="(Все)")+('Парк (SAP)'!$C$11:$C$346=$G4)>0))) -> 2 | C15: =E15-F14 -> 56 | D15: =SUMPRODUCT((((YEAR('Парк (SAP)'!$H$11:$H$346)*12+MONTH('Парк (SAP)'!$H$11:$H$346)-1)+$C5)=(YEAR($A15)*12+MONTH($A15)-1))*((($C4="(Все)")+('Парк (SAP)'!$B$11:$B$346=$C4)>0))*((($G4="(Все)")+('Парк (SAP)'!$C$11:$C$346=$G4)>0))) -> 0 | E15: =SUMPRODUCT(((YEAR('Парк (SAP)'!$H$11:$H$346)*12+MONTH('Парк (SAP)'!$H$11:$H$346)-1)<=(YEAR($A15)*12+MONTH($A15)-1))*((($C4="(Все)")+('Парк (SAP)'!$B$11:$B$346=$C4)>0))*((($G4="(Все)")+('Парк (SAP)'!$C$11:$C$346=$G4)>0))) -> 56 | F15: =SUMPRODUCT((((YEAR('Парк (SAP)'!$H$11:$H$346)*12+MONTH('Парк (SAP)'!$H$11:$H$346)-1)+$C5)<=(YEAR($A15)*12+MONTH($A15)-1))*((($C4="(Все)")+('Парк (SAP)'!$B$11:$B$346=$C4)>0))*((($G4="(Все)")+('Парк (SAP)'!$C$11:$C$346=$G4)>0))) -> 0
A16: 45536 | B16: =SUMPRODUCT(((YEAR('Парк (SAP)'!$H$11:$H$346)*12+MONTH('Парк (SAP)'!$H$11:$H$346)-1)=(YEAR($A16)*12+MONTH($A16)-1))*((($C4="(Все)")+('Парк (SAP)'!$B$11:$B$346=$C4)>0))*((($G4="(Все)")+('Парк (SAP)'!$C$11:$C$346=$G4)>0))) -> 4 | C16: =E16-F15 -> 60 | D16: =SUMPRODUCT((((YEAR('Парк (SAP)'!$H$11:$H$346)*12+MONTH('Парк (SAP)'!$H$11:$H$346)-1)+$C5)=(YEAR($A16)*12+MONTH($A16)-1))*((($C4="(Все)")+('Парк (SAP)'!$B$11:$B$346=$C4)>0))*((($G4="(Все)")+('Парк (SAP)'!$C$11:$C$346=$G4)>0))) -> 0 | E16: =SUMPRODUCT(((YEAR('Парк (SAP)'!$H$11:$H$346)*12+MONTH('Парк (SAP)'!$H$11:$H$346)-1)<=(YEAR($A16)*12+MONTH($A16)-1))*((($C4="(Все)")+('Парк (SAP)'!$B$11:$B$346=$C4)>0))*((($G4="(Все)")+('Парк (SAP)'!$C$11:$C$346=$G4)>0))) -> 60 | F16: =SUMPRODUCT((((YEAR('Парк (SAP)'!$H$11:$H$346)*12+MONTH('Парк (SAP)'!$H$11:$H$346)-1)+$C5)<=(YEAR($A16)*12+MONTH($A16)-1))*((($C4="(Все)")+('Парк (SAP)'!$B$11:$B$346=$C4)>0))*((($G4="(Все)")+('Парк (SAP)'!$C$11:$C$346=$G4)>0))) -> 0
A17: 45566 | B17: =SUMPRODUCT(((YEAR('Парк (SAP)'!$H$11:$H$346)*12+MONTH('Парк (SAP)'!$H$11:$H$346)-1)=(YEAR($A17)*12+MONTH($A17)-1))*((($C4="(Все)")+('Парк (SAP)'!$B$11:$B$346=$C4)>0))*((($G4="(Все)")+('Парк (SAP)'!$C$11:$C$346=$G4)>0))) -> 2 | C17: =E17-F16 -> 62 | D17: =SUMPRODUCT((((YEAR('Парк (SAP)'!$H$11:$H$346)*12+MONTH('Парк (SAP)'!$H$11:$H$346)-1)+$C5)=(YEAR($A17)*12+MONTH($A17)-1))*((($C4="(Все)")+('Парк (SAP)'!$B$11:$B$346=$C4)>0))*((($G4="(Все)")+('Парк (SAP)'!$C$11:$C$346=$G4)>0))) -> 0 | E17: =SUMPRODUCT(((YEAR('Парк (SAP)'!$H$11:$H$346)*12+MONTH('Парк (SAP)'!$H$11:$H$346)-1)<=(YEAR($A17)*12+MONTH($A17)-1))*((($C4="(Все)")+('Парк (SAP)'!$B$11:$B$346=$C4)>0))*((($G4="(Все)")+('Парк (SAP)'!$C$11:$C$346=$G4)>0))) -> 62 | F17: =SUMPRODUCT((((YEAR('Парк (SAP)'!$H$11:$H$346)*12+MONTH('Парк (SAP)'!$H$11:$H$346)-1)+$C5)<=(YEAR($A17)*12+MONTH($A17)-1))*((($C4="(Все)")+('Парк (SAP)'!$B$11:$B$346=$C4)>0))*((($G4="(Все)")+('Парк (SAP)'!$C$11:$C$346=$G4)>0))) -> 0
A18: 45597 | B18: =SUMPRODUCT(((YEAR('Парк (SAP)'!$H$11:$H$346)*12+MONTH('Парк (SAP)'!$H$11:$H$346)-1)=(YEAR($A18)*12+MONTH($A18)-1))*((($C4="(Все)")+('Парк (SAP)'!$B$11:$B$346=$C4)>0))*((($G4="(Все)")+('Парк (SAP)'!$C$11:$C$346=$G4)>0))) -> 0 | C18: =E18-F17 -> 62 | D18: =SUMPRODUCT((((YEAR('Парк (SAP)'!$H$11:$H$346)*12+MONTH('Парк (SAP)'!$H$11:$H$346)-1)+$C5)=(YEAR($A18)*12+MONTH($A18)-1))*((($C4="(Все)")+('Парк (SAP)'!$B$11:$B$346=$C4)>0))*((($G4="(Все)")+('Парк (SAP)'!$C$11:$C$346=$G4)>0))) -> 0 | E18: =SUMPRODUCT(((YEAR('Парк (SAP)'!$H$11:$H$346)*12+MONTH('Парк (SAP)'!$H$11:$H$346)-1)<=(YEAR($A18)*12+MONTH($A18)-1))*((($C4="(Все)")+('Парк (SAP)'!$B$11:$B$346=$C4)>0))*((($G4="(Все)")+('Парк (SAP)'!$C$11:$C$346=$G4)>0))) -> 62 | F18: =SUMPRODUCT((((YEAR('Парк (SAP)'!$H$11:$H$346)*12+MONTH('Парк (SAP)'!$H$11:$H$346)-1)+$C5)<=(YEAR($A18)*12+MONTH($A18)-1))*((($C4="(Все)")+('Парк (SAP)'!$B$11:$B$346=$C4)>0))*((($G4="(Все)")+('Парк (SAP)'!$C$11:$C$346=$G4)>0))) -> 0
A19: 45627 | B19: =SUMPRODUCT(((YEAR('Парк (SAP)'!$H$11:$H$346)*12+MONTH('Парк (SAP)'!$H$11:$H$346)-1)=(YEAR($A19)*12+MONTH($A19)-1))*((($C4="(Все)")+('Парк (SAP)'!$B$11:$B$346=$C4)>0))*((($G4="(Все)")+('Парк (SAP)'!$C$11:$C$346=$G4)>0))) -> 6 | C19: =E19-F18 -> 68 | D19: =SUMPRODUCT((((YEAR('Парк (SAP)'!$H$11:$H$346)*12+MONTH('Парк (SAP)'!$H$11:$H$346)-1)+$C5)=(YEAR($A19)*12+MONTH($A19)-1))*((($C4="(Все)")+('Парк (SAP)'!$B$11:$B$346=$C4)>0))*((($G4="(Все)")+('Парк (SAP)'!$C$11:$C$346=$G4)>0))) -> 0 | E19: =SUMPRODUCT(((YEAR('Парк (SAP)'!$H$11:$H$346)*12+MONTH('Парк (SAP)'!$H$11:$H$346)-1)<=(YEAR($A19)*12+MONTH($A19)-1))*((($C4="(Все)")+('Парк (SAP)'!$B$11:$B$346=$C4)>0))*((($G4="(Все)")+('Парк (SAP)'!$C$11:$C$346=$G4)>0))) -> 68 | F19: =SUMPRODUCT((((YEAR('Парк (SAP)'!$H$11:$H$346)*12+MONTH('Парк (SAP)'!$H$11:$H$346)-1)+$C5)<=(YEAR($A19)*12+MONTH($A19)-1))*((($C4="(Все)")+('Парк (SAP)'!$B$11:$B$346=$C4)>0))*((($G4="(Все)")+('Парк (SAP)'!$C$11:$C$346=$G4)>0))) -> 0
A20: 45658 | B20: =SUMPRODUCT(((YEAR('Парк (SAP)'!$H$11:$H$346)*12+MONTH('Парк (SAP)'!$H$11:$H$346)-1)=(YEAR($A20)*12+MONTH($A20)-1))*((($C4="(Все)")+('Парк (SAP)'!$B$11:$B$346=$C4)>0))*((($G4="(Все)")+('Парк (SAP)'!$C$11:$C$346=$G4)>0))) -> 10 | C20: =E20-F19 -> 78 | D20: =SUMPRODUCT((((YEAR('Парк (SAP)'!$H$11:$H$346)*12+MONTH('Парк (SAP)'!$H$11:$H$346)-1)+$C5)=(YEAR($A20)*12+MONTH($A20)-1))*((($C4="(Все)")+('Парк (SAP)'!$B$11:$B$346=$C4)>0))*((($G4="(Все)")+('Парк (SAP)'!$C$11:$C$346=$G4)>0))) -> 0 | E20: =SUMPRODUCT(((YEAR('Парк (SAP)'!$H$11:$H$346)*12+MONTH('Парк (SAP)'!$H$11:$H$346)-1)<=(YEAR($A20)*12+MONTH($A20)-1))*((($C4="(Все)")+('Парк (SAP)'!$B$11:$B$346=$C4)>0))*((($G4="(Все)")+('Парк (SAP)'!$C$11:$C$346=$G4)>0))) -> 78 | F20: =SUMPRODUCT((((YEAR('Парк (SAP)'!$H$11:$H$346)*12+MONTH('Парк (SAP)'!$H$11:$H$346)-1)+$C5)<=(YEAR($A20)*12+MONTH($A20)-1))*((($C4="(Все)")+('Парк (SAP)'!$B$11:$B$346=$C4)>0))*((($G4="(Все)")+('Парк (SAP)'!$C$11:$C$346=$G4)>0))) -> 0
A21: 45689 | B21: =SUMPRODUCT(((YEAR('Парк (SAP)'!$H$11:$H$346)*12+MONTH('Парк (SAP)'!$H$11:$H$346)-1)=(YEAR($A21)*12+MONTH($A21)-1))*((($C4="(Все)")+('Парк (SAP)'!$B$11:$B$346=$C4)>0))*((($G4="(Все)")+('Парк (SAP)'!$C$11:$C$346=$G4)>0))) -> 9 | C21: =E21-F20 -> 87 | D21: =SUMPRODUCT((((YEAR('Парк (SAP)'!$H$11:$H$346)*12+MONTH('Парк (SAP)'!$H$11:$H$346)-1)+$C5)=(YEAR($A21)*12+MONTH($A21)-1))*((($C4="(Все)")+('Парк (SAP)'!$B$11:$B$346=$C4)>0))*((($G4="(Все)")+('Парк (SAP)'!$C$11:$C$346=$G4)>0))) -> 0 | E21: =SUMPRODUCT(((YEAR('Парк (SAP)'!$H$11:$H$346)*12+MONTH('Парк (SAP)'!$H$11:$H$346)-1)<=(YEAR($A21)*12+MONTH($A21)-1))*((($C4="(Все)")+('Парк (SAP)'!$B$11:$B$346=$C4)>0))*((($G4="(Все)")+('Парк (SAP)'!$C$11:$C$346=$G4)>0))) -> 87 | F21: =SUMPRODUCT((((YEAR('Парк (SAP)'!$H$11:$H$346)*12+MONTH('Парк (SAP)'!$H$11:$H$346)-1)+$C5)<=(YEAR($A21)*12+MONTH($A21)-1))*((($C4="(Все)")+('Парк (SAP)'!$B$11:$B$346=$C4)>0))*((($G4="(Все)")+('Парк (SAP)'!$C$11:$C$346=$G4)>0))) -> 0
A22: 45717 | B22: =SUMPRODUCT(((YEAR('Парк (SAP)'!$H$11:$H$346)*12+MONTH('Парк (SAP)'!$H$11:$H$346)-1)=(YEAR($A22)*12+MONTH($A22)-1))*((($C4="(Все)")+('Парк (SAP)'!$B$11:$B$346=$C4)>0))*((($G4="(Все)")+('Парк (SAP)'!$C$11:$C$346=$G4)>0))) -> 13 | C22: =E22-F21 -> 100 | D22: =SUMPRODUCT((((YEAR('Парк (SAP)'!$H$11:$H$346)*12+MONTH('Парк (SAP)'!$H$11:$H$346)-1)+$C5)=(YEAR($A22)*12+MONTH($A22)-1))*((($C4="(Все)")+('Парк (SAP)'!$B$11:$B$346=$C4)>0))*((($G4="(Все)")+('Парк (SAP)'!$C$11:$C$346=$G4)>0))) -> 0 | E22: =SUMPRODUCT(((YEAR('Парк (SAP)'!$H$11:$H$346)*12+MONTH('Парк (SAP)'!$H$11:$H$346)-1)<=(YEAR($A22)*12+MONTH($A22)-1))*((($C4="(Все)")+('Парк (SAP)'!$B$11:$B$346=$C4)>0))*((($G4="(Все)")+('Парк (SAP)'!$C$11:$C$346=$G4)>0))) -> 100 | F22: =SUMPRODUCT((((YEAR('Парк (SAP)'!$H$11:$H$346)*12+MONTH('Парк (SAP)'!$H$11:$H$346)-1)+$C5)<=(YEAR($A22)*12+MONTH($A22)-1))*((($C4="(Все)")+('Парк (SAP)'!$B$11:$B$346=$C4)>0))*((($G4="(Все)")+('Парк (SAP)'!$C$11:$C$346=$G4)>0))) -> 0
A23: 45748 | B23: =SUMPRODUCT(((YEAR('Парк (SAP)'!$H$11:$H$346)*12+MONTH('Парк (SAP)'!$H$11:$H$346)-1)=(YEAR($A23)*12+MONTH($A23)-1))*((($C4="(Все)")+('Парк (SAP)'!$B$11:$B$346=$C4)>0))*((($G4="(Все)")+('Парк (SAP)'!$C$11:$C$346=$G4)>0))) -> 7 | C23: =E23-F22 -> 107 | D23: =SUMPRODUCT((((YEAR('Парк (SAP)'!$H$11:$H$346)*12+MONTH('Парк (SAP)'!$H$11:$H$346)-1)+$C5)=(YEAR($A23)*12+MONTH($A23)-1))*((($C4="(Все)")+('Парк (SAP)'!$B$11:$B$346=$C4)>0))*((($G4="(Все)")+('Парк (SAP)'!$C$11:$C$346=$G4)>0))) -> 0 | E23: =SUMPRODUCT(((YEAR('Парк (SAP)'!$H$11:$H$346)*12+MONTH('Парк (SAP)'!$H$11:$H$346)-1)<=(YEAR($A23)*12+MONTH($A23)-1))*((($C4="(Все)")+('Парк (SAP)'!$B$11:$B$346=$C4)>0))*((($G4="(Все)")+('Парк (SAP)'!$C$11:$C$346=$G4)>0))) -> 107 | F23: =SUMPRODUCT((((YEAR('Парк (SAP)'!$H$11:$H$346)*12+MONTH('Парк (SAP)'!$H$11:$H$346)-1)+$C5)<=(YEAR($A23)*12+MONTH($A23)-1))*((($C4="(Все)")+('Парк (SAP)'!$B$11:$B$346=$C4)>0))*((($G4="(Все)")+('Парк (SAP)'!$C$11:$C$346=$G4)>0))) -> 0
A24: 45778 | B24: =SUMPRODUCT(((YEAR('Парк (SAP)'!$H$11:$H$346)*12+MONTH('Парк (SAP)'!$H$11:$H$346)-1)=(YEAR($A24)*12+MONTH($A24)-1))*((($C4="(Все)")+('Парк (SAP)'!$B$11:$B$346=$C4)>0))*((($G4="(Все)")+('Парк (SAP)'!$C$11:$C$346=$G4)>0))) -> 4 | C24: =E24-F23 -> 111 | D24: =SUMPRODUCT((((YEAR('Парк (SAP)'!$H$11:$H$346)*12+MONTH('Парк (SAP)'!$H$11:$H$346)-1)+$C5)=(YEAR($A24)*12+MONTH($A24)-1))*((($C4="(Все)")+('Парк (SAP)'!$B$11:$B$346=$C4)>0))*((($G4="(Все)")+('Парк (SAP)'!$C$11:$C$346=$G4)>0))) -> 0 | E24: =SUMPRODUCT(((YEAR('Парк (SAP)'!$H$11:$H$346)*12+MONTH('Парк (SAP)'!$H$11:$H$346)-1)<=(YEAR($A24)*12+MONTH($A24)-1))*((($C4="(Все)")+('Парк (SAP)'!$B$11:$B$346=$C4)>0))*((($G4="(Все)")+('Парк (SAP)'!$C$11:$C$346=$G4)>0))) -> 111 | F24: =SUMPRODUCT((((YEAR('Парк (SAP)'!$H$11:$H$346)*12+MONTH('Парк (SAP)'!$H$11:$H$346)-1)+$C5)<=(YEAR($A24)*12+MONTH($A24)-1))*((($C4="(Все)")+('Парк (SAP)'!$B$11:$B$346=$C4)>0))*((($G4="(Все)")+('Парк (SAP)'!$C$11:$C$346=$G4)>0))) -> 0
A25: 45809 | B25: =SUMPRODUCT(((YEAR('Парк (SAP)'!$H$11:$H$346)*12+MONTH('Парк (SAP)'!$H$11:$H$346)-1)=(YEAR($A25)*12+MONTH($A25)-1))*((($C4="(Все)")+('Парк (SAP)'!$B$11:$B$346=$C4)>0))*((($G4="(Все)")+('Парк (SAP)'!$C$11:$C$346=$G4)>0))) -> 4 | C25: =E25-F24 -> 115 | D25: =SUMPRODUCT((((YEAR('Парк (SAP)'!$H$11:$H$346)*12+MONTH('Парк (SAP)'!$H$11:$H$346)-1)+$C5)=(YEAR($A25)*12+MONTH($A25)-1))*((($C4="(Все)")+('Парк (SAP)'!$B$11:$B$346=$C4)>0))*((($G4="(Все)")+('Парк (SAP)'!$C$11:$C$346=$G4)>0))) -> 0 | E25: =SUMPRODUCT(((YEAR('Парк (SAP)'!$H$11:$H$346)*12+MONTH('Парк (SAP)'!$H$11:$H$346)-1)<=(YEAR($A25)*12+MONTH($A25)-1))*((($C4="(Все)")+('Парк (SAP)'!$B$11:$B$346=$C4)>0))*((($G4="(Все)")+('Парк (SAP)'!$C$11:$C$346=$G4)>0))) -> 115 | F25: =SUMPRODUCT((((YEAR('Парк (SAP)'!$H$11:$H$346)*12+MONTH('Парк (SAP)'!$H$11:$H$346)-1)+$C5)<=(YEAR($A25)*12+MONTH($A25)-1))*((($C4="(Все)")+('Парк (SAP)'!$B$11:$B$346=$C4)>0))*((($G4="(Все)")+('Парк (SAP)'!$C$11:$C$346=$G4)>0))) -> 0
A26: 45839 | B26: =SUMPRODUCT(((YEAR('Парк (SAP)'!$H$11:$H$346)*12+MONTH('Парк (SAP)'!$H$11:$H$346)-1)=(YEAR($A26)*12+MONTH($A26)-1))*((($C4="(Все)")+('Парк (SAP)'!$B$11:$B$346=$C4)>0))*((($G4="(Все)")+('Парк (SAP)'!$C$11:$C$346=$G4)>0))) -> 7 | C26: =E26-F25 -> 122 | D26: =SUMPRODUCT((((YEAR('Парк (SAP)'!$H$11:$H$346)*12+MONTH('Парк (SAP)'!$H$11:$H$346)-1)+$C5)=(YEAR($A26)*12+MONTH($A26)-1))*((($C4="(Все)")+('Парк (SAP)'!$B$11:$B$346=$C4)>0))*((($G4="(Все)")+('Парк (SAP)'!$C$11:$C$346=$G4)>0))) -> 0 | E26: =SUMPRODUCT(((YEAR('Парк (SAP)'!$H$11:$H$346)*12+MONTH('Парк (SAP)'!$H$11:$H$346)-1)<=(YEAR($A26)*12+MONTH($A26)-1))*((($C4="(Все)")+('Парк (SAP)'!$B$11:$B$346=$C4)>0))*((($G4="(Все)")+('Парк (SAP)'!$C$11:$C$346=$G4)>0))) -> 122 | F26: =SUMPRODUCT((((YEAR('Парк (SAP)'!$H$11:$H$346)*12+MONTH('Парк (SAP)'!$H$11:$H$346)-1)+$C5)<=(YEAR($A26)*12+MONTH($A26)-1))*((($C4="(Все)")+('Парк (SAP)'!$B$11:$B$346=$C4)>0))*((($G4="(Все)")+('Парк (SAP)'!$C$11:$C$346=$G4)>0))) -> 0
A27: 45870 | B27: =SUMPRODUCT(((YEAR('Парк (SAP)'!$H$11:$H$346)*12+MONTH('Парк (SAP)'!$H$11:$H$346)-1)=(YEAR($A27)*12+MONTH($A27)-1))*((($C4="(Все)")+('Парк (SAP)'!$B$11:$B$346=$C4)>0))*((($G4="(Все)")+('Парк (SAP)'!$C$11:$C$346=$G4)>0))) -> 5 | C27: =E27-F26 -> 127 | D27: =SUMPRODUCT((((YEAR('Парк (SAP)'!$H$11:$H$346)*12+MONTH('Парк (SAP)'!$H$11:$H$346)-1)+$C5)=(YEAR($A27)*12+MONTH($A27)-1))*((($C4="(Все)")+('Парк (SAP)'!$B$11:$B$346=$C4)>0))*((($G4="(Все)")+('Парк (SAP)'!$C$11:$C$346=$G4)>0))) -> 0 | E27: =SUMPRODUCT(((YEAR('Парк (SAP)'!$H$11:$H$346)*12+MONTH('Парк (SAP)'!$H$11:$H$346)-1)<=(YEAR($A27)*12+MONTH($A27)-1))*((($C4="(Все)")+('Парк (SAP)'!$B$11:$B$346=$C4)>0))*((($G4="(Все)")+('Парк (SAP)'!$C$11:$C$346=$G4)>0))) -> 127 | F27: =SUMPRODUCT((((YEAR('Парк (SAP)'!$H$11:$H$346)*12+MONTH('Парк (SAP)'!$H$11:$H$346)-1)+$C5)<=(YEAR($A27)*12+MONTH($A27)-1))*((($C4="(Все)")+('Парк (SAP)'!$B$11:$B$346=$C4)>0))*((($G4="(Все)")+('Парк (SAP)'!$C$11:$C$346=$G4)>0))) -> 0
A28: 45901 | B28: =SUMPRODUCT(((YEAR('Парк (SAP)'!$H$11:$H$346)*12+MONTH('Парк (SAP)'!$H$11:$H$346)-1)=(YEAR($A28)*12+MONTH($A28)-1))*((($C4="(Все)")+('Парк (SAP)'!$B$11:$B$346=$C4)>0))*((($G4="(Все)")+('Парк (SAP)'!$C$11:$C$346=$G4)>0))) -> 9 | C28: =E28-F27 -> 136 | D28: =SUMPRODUCT((((YEAR('Парк (SAP)'!$H$11:$H$346)*12+MONTH('Парк (SAP)'!$H$11:$H$346)-1)+$C5)=(YEAR($A28)*12+MONTH($A28)-1))*((($C4="(Все)")+('Парк (SAP)'!$B$11:$B$346=$C4)>0))*((($G4="(Все)")+('Парк (SAP)'!$C$11:$C$346=$G4)>0))) -> 0 | E28: =SUMPRODUCT(((YEAR('Парк (SAP)'!$H$11:$H$346)*12+MONTH('Парк (SAP)'!$H$11:$H$346)-1)<=(YEAR($A28)*12+MONTH($A28)-1))*((($C4="(Все)")+('Парк (SAP)'!$B$11:$B$346=$C4)>0))*((($G4="(Все)")+('Парк (SAP)'!$C$11:$C$346=$G4)>0))) -> 136 | F28: =SUMPRODUCT((((YEAR('Парк (SAP)'!$H$11:$H$346)*12+MONTH('Парк (SAP)'!$H$11:$H$346)-1)+$C5)<=(YEAR($A28)*12+MONTH($A28)-1))*((($C4="(Все)")+('Парк (SAP)'!$B$11:$B$346=$C4)>0))*((($G4="(Все)")+('Парк (SAP)'!$C$11:$C$346=$G4)>0))) -> 0
A29: 45931 | B29: =SUMPRODUCT(((YEAR('Парк (SAP)'!$H$11:$H$346)*12+MONTH('Парк (SAP)'!$H$11:$H$346)-1)=(YEAR($A29)*12+MONTH($A29)-1))*((($C4="(Все)")+('Парк (SAP)'!$B$11:$B$346=$C4)>0))*((($G4="(Все)")+('Парк (SAP)'!$C$11:$C$346=$G4)>0))) -> 8 | C29: =E29-F28 -> 144 | D29: =SUMPRODUCT((((YEAR('Парк (SAP)'!$H$11:$H$346)*12+MONTH('Парк (SAP)'!$H$11:$H$346)-1)+$C5)=(YEAR($A29)*12+MONTH($A29)-1))*((($C4="(Все)")+('Парк (SAP)'!$B$11:$B$346=$C4)>0))*((($G4="(Все)")+('Парк (SAP)'!$C$11:$C$346=$G4)>0))) -> 0 | E29: =SUMPRODUCT(((YEAR('Парк (SAP)'!$H$11:$H$346)*12+MONTH('Парк (SAP)'!$H$11:$H$346)-1)<=(YEAR($A29)*12+MONTH($A29)-1))*((($C4="(Все)")+('Парк (SAP)'!$B$11:$B$346=$C4)>0))*((($G4="(Все)")+('Парк (SAP)'!$C$11:$C$346=$G4)>0))) -> 144 | F29: =SUMPRODUCT((((YEAR('Парк (SAP)'!$H$11:$H$346)*12+MONTH('Парк (SAP)'!$H$11:$H$346)-1)+$C5)<=(YEAR($A29)*12+MONTH($A29)-1))*((($C4="(Все)")+('Парк (SAP)'!$B$11:$B$346=$C4)>0))*((($G4="(Все)")+('Парк (SAP)'!$C$11:$C$346=$G4)>0))) -> 0
A30: 45962 | B30: =SUMPRODUCT(((YEAR('Парк (SAP)'!$H$11:$H$346)*12+MONTH('Парк (SAP)'!$H$11:$H$346)-1)=(YEAR($A30)*12+MONTH($A30)-1))*((($C4="(Все)")+('Парк (SAP)'!$B$11:$B$346=$C4)>0))*((($G4="(Все)")+('Парк (SAP)'!$C$11:$C$346=$G4)>0))) -> 1 | C30: =E30-F29 -> 145 | D30: =SUMPRODUCT((((YEAR('Парк (SAP)'!$H$11:$H$346)*12+MONTH('Парк (SAP)'!$H$11:$H$346)-1)+$C5)=(YEAR($A30)*12+MONTH($A30)-1))*((($C4="(Все)")+('Парк (SAP)'!$B$11:$B$346=$C4)>0))*((($G4="(Все)")+('Парк (SAP)'!$C$11:$C$346=$G4)>0))) -> 0 | E30: =SUMPRODUCT(((YEAR('Парк (SAP)'!$H$11:$H$346)*12+MONTH('Парк (SAP)'!$H$11:$H$346)-1)<=(YEAR($A30)*12+MONTH($A30)-1))*((($C4="(Все)")+('Парк (SAP)'!$B$11:$B$346=$C4)>0))*((($G4="(Все)")+('Парк (SAP)'!$C$11:$C$346=$G4)>0))) -> 145 | F30: =SUMPRODUCT((((YEAR('Парк (SAP)'!$H$11:$H$346)*12+MONTH('Парк (SAP)'!$H$11:$H$346)-1)+$C5)<=(YEAR($A30)*12+MONTH($A30)-1))*((($C4="(Все)")+('Парк (SAP)'!$B$11:$B$346=$C4)>0))*((($G4="(Все)")+('Парк (SAP)'!$C$11:$C$346=$G4)>0))) -> 0
A31: 45992 | B31: =SUMPRODUCT(((YEAR('Парк (SAP)'!$H$11:$H$346)*12+MONTH('Парк (SAP)'!$H$11:$H$346)-1)=(YEAR($A31)*12+MONTH($A31)-1))*((($C4="(Все)")+('Парк (SAP)'!$B$11:$B$346=$C4)>0))*((($G4="(Все)")+('Парк (SAP)'!$C$11:$C$346=$G4)>0))) -> 7 | C31: =E31-F30 -> 152 | D31: =SUMPRODUCT((((YEAR('Парк (SAP)'!$H$11:$H$346)*12+MONTH('Парк (SAP)'!$H$11:$H$346)-1)+$C5)=(YEAR($A31)*12+MONTH($A31)-1))*((($C4="(Все)")+('Парк (SAP)'!$B$11:$B$346=$C4)>0))*((($G4="(Все)")+('Парк (SAP)'!$C$11:$C$346=$G4)>0))) -> 0 | E31: =SUMPRODUCT(((YEAR('Парк (SAP)'!$H$11:$H$346)*12+MONTH('Парк (SAP)'!$H$11:$H$346)-1)<=(YEAR($A31)*12+MONTH($A31)-1))*((($C4="(Все)")+('Парк (SAP)'!$B$11:$B$346=$C4)>0))*((($G4="(Все)")+('Парк (SAP)'!$C$11:$C$346=$G4)>0))) -> 152 | F31: =SUMPRODUCT((((YEAR('Парк (SAP)'!$H$11:$H$346)*12+MONTH('Парк (SAP)'!$H$11:$H$346)-1)+$C5)<=(YEAR($A31)*12+MONTH($A31)-1))*((($C4="(Все)")+('Парк (SAP)'!$B$11:$B$346=$C4)>0))*((($G4="(Все)")+('Парк (SAP)'!$C$11:$C$346=$G4)>0))) -> 0
A32: 46023 | B32: =SUMPRODUCT(((YEAR('Парк (SAP)'!$H$11:$H$346)*12+MONTH('Парк (SAP)'!$H$11:$H$346)-1)=(YEAR($A32)*12+MONTH($A32)-1))*((($C4="(Все)")+('Парк (SAP)'!$B$11:$B$346=$C4)>0))*((($G4="(Все)")+('Парк (SAP)'!$C$11:$C$346=$G4)>0))) -> 6 | C32: =E32-F31 -> 158 | D32: =SUMPRODUCT((((YEAR('Парк (SAP)'!$H$11:$H$346)*12+MONTH('Парк (SAP)'!$H$11:$H$346)-1)+$C5)=(YEAR($A32)*12+MONTH($A32)-1))*((($C4="(Все)")+('Парк (SAP)'!$B$11:$B$346=$C4)>0))*((($G4="(Все)")+('Парк (SAP)'!$C$11:$C$346=$G4)>0))) -> 0 | E32: =SUMPRODUCT(((YEAR('Парк (SAP)'!$H$11:$H$346)*12+MONTH('Парк (SAP)'!$H$11:$H$346)-1)<=(YEAR($A32)*12+MONTH($A32)-1))*((($C4="(Все)")+('Парк (SAP)'!$B$11:$B$346=$C4)>0))*((($G4="(Все)")+('Парк (SAP)'!$C$11:$C$346=$G4)>0))) -> 158 | F32: =SUMPRODUCT((((YEAR('Парк (SAP)'!$H$11:$H$346)*12+MONTH('Парк (SAP)'!$H$11:$H$346)-1)+$C5)<=(YEAR($A32)*12+MONTH($A32)-1))*((($C4="(Все)")+('Парк (SAP)'!$B$11:$B$346=$C4)>0))*((($G4="(Все)")+('Парк (SAP)'!$C$11:$C$346=$G4)>0))) -> 0
A33: 46054 | B33: =SUMPRODUCT(((YEAR('Парк (SAP)'!$H$11:$H$346)*12+MONTH('Парк (SAP)'!$H$11:$H$346)-1)=(YEAR($A33)*12+MONTH($A33)-1))*((($C4="(Все)")+('Парк (SAP)'!$B$11:$B$346=$C4)>0))*((($G4="(Все)")+('Парк (SAP)'!$C$11:$C$346=$G4)>0))) -> 11 | C33: =E33-F32 -> 169 | D33: =SUMPRODUCT((((YEAR('Парк (SAP)'!$H$11:$H$346)*12+MONTH('Парк (SAP)'!$H$11:$H$346)-1)+$C5)=(YEAR($A33)*12+MONTH($A33)-1))*((($C4="(Все)")+('Парк (SAP)'!$B$11:$B$346=$C4)>0))*((($G4="(Все)")+('Парк (SAP)'!$C$11:$C$346=$G4)>0))) -> 9 | E33: =SUMPRODUCT(((YEAR('Парк (SAP)'!$H$11:$H$346)*12+MONTH('Парк (SAP)'!$H$11:$H$346)-1)<=(YEAR($A33)*12+MONTH($A33)-1))*((($C4="(Все)")+('Парк (SAP)'!$B$11:$B$346=$C4)>0))*((($G4="(Все)")+('Парк (SAP)'!$C$11:$C$346=$G4)>0))) -> 169 | F33: =SUMPRODUCT((((YEAR('Парк (SAP)'!$H$11:$H$346)*12+MONTH('Парк (SAP)'!$H$11:$H$346)-1)+$C5)<=(YEAR($A33)*12+MONTH($A33)-1))*((($C4="(Все)")+('Парк (SAP)'!$B$11:$B$346=$C4)>0))*((($G4="(Все)")+('Парк (SAP)'!$C$11:$C$346=$G4)>0))) -> 9
A34: 46082 | B34: =SUMPRODUCT(((YEAR('Парк (SAP)'!$H$11:$H$346)*12+MONTH('Парк (SAP)'!$H$11:$H$346)-1)=(YEAR($A34)*12+MONTH($A34)-1))*((($C4="(Все)")+('Парк (SAP)'!$B$11:$B$346=$C4)>0))*((($G4="(Все)")+('Парк (SAP)'!$C$11:$C$346=$G4)>0))) -> 13 | C34: =E34-F33 -> 173 | D34: =SUMPRODUCT((((YEAR('Парк (SAP)'!$H$11:$H$346)*12+MONTH('Парк (SAP)'!$H$11:$H$346)-1)+$C5)=(YEAR($A34)*12+MONTH($A34)-1))*((($C4="(Все)")+('Парк (SAP)'!$B$11:$B$346=$C4)>0))*((($G4="(Все)")+('Парк (SAP)'!$C$11:$C$346=$G4)>0))) -> 10 | E34: =SUMPRODUCT(((YEAR('Парк (SAP)'!$H$11:$H$346)*12+MONTH('Парк (SAP)'!$H$11:$H$346)-1)<=(YEAR($A34)*12+MONTH($A34)-1))*((($C4="(Все)")+('Парк (SAP)'!$B$11:$B$346=$C4)>0))*((($G4="(Все)")+('Парк (SAP)'!$C$11:$C$346=$G4)>0))) -> 182 | F34: =SUMPRODUCT((((YEAR('Парк (SAP)'!$H$11:$H$346)*12+MONTH('Парк (SAP)'!$H$11:$H$346)-1)+$C5)<=(YEAR($A34)*12+MONTH($A34)-1))*((($C4="(Все)")+('Парк (SAP)'!$B$11:$B$346=$C4)>0))*((($G4="(Все)")+('Парк (SAP)'!$C$11:$C$346=$G4)>0))) -> 19
A35: 46113 | B35: =SUMPRODUCT(((YEAR('Парк (SAP)'!$H$11:$H$346)*12+MONTH('Парк (SAP)'!$H$11:$H$346)-1)=(YEAR($A35)*12+MONTH($A35)-1))*((($C4="(Все)")+('Парк (SAP)'!$B$11:$B$346=$C4)>0))*((($G4="(Все)")+('Парк (SAP)'!$C$11:$C$346=$G4)>0))) -> 9 | C35: =E35-F34 -> 172 | D35: =SUMPRODUCT((((YEAR('Парк (SAP)'!$H$11:$H$346)*12+MONTH('Парк (SAP)'!$H$11:$H$346)-1)+$C5)=(YEAR($A35)*12+MONTH($A35)-1))*((($C4="(Все)")+('Парк (SAP)'!$B$11:$B$346=$C4)>0))*((($G4="(Все)")+('Парк (SAP)'!$C$11:$C$346=$G4)>0))) -> 10 | E35: =SUMPRODUCT(((YEAR('Парк (SAP)'!$H$11:$H$346)*12+MONTH('Парк (SAP)'!$H$11:$H$346)-1)<=(YEAR($A35)*12+MONTH($A35)-1))*((($C4="(Все)")+('Парк (SAP)'!$B$11:$B$346=$C4)>0))*((($G4="(Все)")+('Парк (SAP)'!$C$11:$C$346=$G4)>0))) -> 191 | F35: =SUMPRODUCT((((YEAR('Парк (SAP)'!$H$11:$H$346)*12+MONTH('Парк (SAP)'!$H$11:$H$346)-1)+$C5)<=(YEAR($A35)*12+MONTH($A35)-1))*((($C4="(Все)")+('Парк (SAP)'!$B$11:$B$346=$C4)>0))*((($G4="(Все)")+('Парк (SAP)'!$C$11:$C$346=$G4)>0))) -> 29
